Workbook

Sheet Input-Variablen
B3: Input variables
C5: " | D5: ID_Dataset | E5: ", | H5: =_xlfn.CONCAT(C5:F5) -> "ID_Dataset",
C6: " | D6: Name_Variant | E6: ", | H6: =_xlfn.CONCAT(C6:F6) -> "Name_Variant",
C7: " | D7: Year_State | E7: ", | H7: =_xlfn.CONCAT(C7:F7) -> "Year_State",
C8: " | D8: Year_State_First | E8: ", | H8: =_xlfn.CONCAT(C8:F8) -> "Year_State_First",
C9: " | D9: Year_State_Last | E9: ", | H9: =_xlfn.CONCAT(C9:F9) -> "Year_State_Last",
C10: " | D10: Year_Building | E10: ", | H10: =_xlfn.CONCAT(C10:F10) -> "Year_Building",
C11: " | D11: ID_Zone_LocationBuilding | E11: ", | H11: =_xlfn.CONCAT(C11:F11) -> "ID_Zone_LocationBuilding",
C12: " | D12: n_Block | E12: ", | H12: =_xlfn.CONCAT(C12:F12) -> "n_Block",
C13: " | D13: n_House | E13: ", | H13: =_xlfn.CONCAT(C13:F13) -> "n_House",
C14: " | D14: n_Storey | E14: ", | H14: =_xlfn.CONCAT(C14:F14) -> "n_Storey",
C15: " | D15: n_Dwelling | E15: ", | H15: =_xlfn.CONCAT(C15:F15) -> "n_Dwelling",
C16: " | D16: A_C_Floor_Intake | E16: ", | H16: =_xlfn.CONCAT(C16:F16) -> "A_C_Floor_Intake",
... C49: " | D49: f_Insulation_Floor | E49: ", | H49: =_xlfn.CONCAT(C49:F49) -> "f_Insulation_Floor",
C50: " | E50: ", | H50: =_xlfn.CONCAT(C50:F50) -> "",
C51: " | E51: ", | H51: =_xlfn.CONCAT(C51:F51) -> "",
C53: " | D53: Code_CentralisationType_SysHG | E53: ", | H53: =_xlfn.CONCAT(C53:F53) -> "Code_CentralisationType_SysHG",
H54: =_xlfn.CONCAT(C54:F54)
C55: " | D55: Indicator_Storage_SysH | E55: ", | H55: =_xlfn.CONCAT(C55:F55) -> "Indicator_Storage_SysH",
C56: " | D56: Indicator_Storage_SysH_Immersion | E56: ", | H56: =_xlfn.CONCAT(C56:F56) -> "Indicator_Storage_SysH_Immersion",
C57: " | D57: Indicator_Storage_SysH_InsideEnvelope | E57: ", | H57: =_xlfn.CONCAT(C57:F57) -> "Indicator_Storage_SysH_InsideEnvelope",
H58: =_xlfn.CONCAT(C58:F58)
C59: " | D59: Indicator_Distribution_SysH | E59: ", | H59: =_xlfn.CONCAT(C59:F59) -> "Indicator_Distribution_SysH",
C60: " | D60: Indicator_Distribution_SysH_OutsideEnvelope | E60: ", | H60: =_xlfn.CONCAT(C60:F60) -> "Indicator_Distribution_SysH_OutsideEnvelope",
C61: " | D61: Indicator_Distribution_SysH_PoorlyInsulated | E61: ", | H61: =_xlfn.CONCAT(C61:F61) -> "Indicator_Distribution_SysH_PoorlyInsulated",
C62: " | D62: Indicator_Distribution_SysH_LowTemperature | E62: ", | H62: =_xlfn.CONCAT(C62:F62) -> "Indicator_Distribution_SysH_LowTemperature",
H63: =_xlfn.CONCAT(C63:F63)
C64: " | D64: Indicator_Storage_SysW | E64: ", | H64: =_xlfn.CONCAT(C64:F64) -> "Indicator_Storage_SysW",
C65: " | D65: Indicator_Storage_SysW_Immersion | E65: ", | H65: =_xlfn.CONCAT(C65:F65) -> "Indicator_Storage_SysW_Immersion",
C66: " | D66: Indicator_Storage_SysW_InsideEnvelope | E66: ", | H66: =_xlfn.CONCAT(C66:F66) -> "Indicator_Storage_SysW_InsideEnvelope",
H67: =_xlfn.CONCAT(C67:F67)
C68: " | D68: Indicator_Distribution_SysW | E68: ", | H68: =_xlfn.CONCAT(C68:F68) -> "Indicator_Distribution_SysW",
C69: " | D69: Indicator_Distribution_SysW_CirculationLoop | E69: ", | H69: =_xlfn.CONCAT(C69:F69) -> "Indicator_Distribution_SysW_CirculationLoop",
C70: " | D70: Indicator_Distribution_SysW_OutsideEnvelope | E70: ", | H70: =_xlfn.CONCAT(C70:F70) -> "Indicator_Distribution_SysW_OutsideEnvelope",
C71: " | D71: Indicator_Distribution_SysW_PoorlyInsulated | E71: ", | H71: =_xlfn.CONCAT(C71:F71) -> "Indicator_Distribution_SysW_PoorlyInsulated",
C72: " | E72: ", | H72: =_xlfn.CONCAT(C72:F72) -> "",
C73: " | E73: ", | H73: =_xlfn.CONCAT(C73:F73) -> "",
C74: " | E74: ", | H74: =_xlfn.CONCAT(C74:F74) -> "",
C75: " | E75: ", | H75: =_xlfn.CONCAT(C75:F75) -> "",
C76: " | E76: ", | H76: =_xlfn.CONCAT(C76:F76) -> "",
...

Sheet DF_BuildingTypeMatrix
A1: =Matrix!A1 -> Index_Row | B1: =Matrix!B1 -> Display_Region | C1: =Matrix!C1 -> Display_ConstructionYearClass | D1: =Matrix!D1 -> Display_AdditionalParameter | E1: =Matrix!E1 -> Code_BuildingType_Column1 | F1: =Matrix!F1 -> Code_BuildingType_Column2 | G1: =Matrix!G1 -> Code_BuildingType_Column3 | H1: =Matrix!H1 -> Code_BuildingType_Column4 | I1: =Matrix!J1 -> Code_Country | J1: =Matrix!K1 -> Code_TypologyRegion | K1: =Matrix!L1 -> Name_TypologyRegion | L1: =Matrix!M1 -> Name_National_TypologyRegion | M1: =Matrix!N1 -> Number_ConstructionYearClass | N1: =Matrix!O1 -> ConstructionYearClass_FirstYear | O1: =Matrix!P1 -> ConstructionYearClass_LastYear | P1: =Matrix!Q1 -> Code_AdditionalParameter | ... T1: =Matrix!U1 -> Note_DataBaseAdmin | U1: =Matrix!W1 -> Suffix_Building_Column1 | V1: =Matrix!X1 -> Suffix_Building_Column2 | W1: =Matrix!Y1 -> Suffix_Building_Column3 | X1: =Matrix!Z1 -> Suffix_Building_Column4 | Y1: Code_ConstructionYearClass_National | Z1: Code_BuildingType_National_Column1 | AA1: Code_BuildingType_National_Column2 | AB1: Code_BuildingType_National_Column3 | AC1: Code_BuildingType_National_Column4 | AD1: Date_Change
A2: =Matrix!A11 -> 1 | B2: =Matrix!B11 -> National (nicht regional spezifiziert) | C2: =Matrix!C11 -> ... 1859 | D2: =Matrix!D11 -> Generic (Basis-Typ) | E2: =Matrix!E11 -> DE.N.SFH.01.Gen | F2: =Matrix!F11 | G2: =Matrix!G11 -> DE.N.MFH.01.Gen | H2: =Matrix!H11 | I2: =Matrix!J11 -> DE | J2: =Matrix!K11 -> N | K2: =Matrix!L11 -> National | L2: =Matrix!M11 -> nicht regional spezifiziert | M2: =Matrix!N11 -> 1 | N2: =Matrix!O11 -> 0 | O2: =Matrix!P11 -> 1859 | P2: =Matrix!Q11 -> Gen | ... T2: =Matrix!U11 -> 0 | U2: =Matrix!W11 -> ReEx.001 | V2: =Matrix!X11 -> 0 | W2: =Matrix!Y11 -> ReEx.001 | X2: =Matrix!Z11 -> 0 | Y2: A | Z2: ="EFH_"&$Y2 -> EFH_A | AA2: ="RH_"&$Y2 -> RH_A | AB2: ="MFH_"&$Y2 -> MFH_A | AC2: ="GMH_"&$Y2 -> GMH_A | AD2: 45751
A3: =Matrix!A12 -> 2 | B3: =Matrix!B12 -> National (nicht regional spezifiziert) | C3: =Matrix!C12 -> 1860 ... 1918 | D3: =Matrix!D12 -> Generic (Basis-Typ) | E3: =Matrix!E12 -> DE.N.SFH.02.Gen | F3: =Matrix!F12 -> DE.N.TH.02.Gen | G3: =Matrix!G12 -> DE.N.MFH.02.Gen | H3: =Matrix!H12 -> DE.N.AB.02.Gen | I3: =Matrix!J12 -> DE | J3: =Matrix!K12 -> N | K3: =Matrix!L12 -> National | L3: =Matrix!M12 -> nicht regional spezifiziert | M3: =Matrix!N12 -> 2 | N3: =Matrix!O12 -> 1860 | O3: =Matrix!P12 -> 1918 | P3: =Matrix!Q12 -> Gen | ... T3: =Matrix!U12 -> 0 | U3: =Matrix!W12 -> ReEx.001 | V3: =Matrix!X12 -> ReEx.001 | W3: =Matrix!Y12 -> ReEx.001 | X3: =Matrix!Z12 -> ReEx.001 | Y3: B | Z3: ="EFH_"&$Y3 -> EFH_B | AA3: ="RH_"&$Y3 -> RH_B | AB3: ="MFH_"&$Y3 -> MFH_B | AC3: ="GMH_"&$Y3 -> GMH_B | AD3: 45751
A4: =Matrix!A13 -> 3 | B4: =Matrix!B13 -> National (nicht regional spezifiziert) | C4: =Matrix!C13 -> 1919 ... 1948 | D4: =Matrix!D13 -> Generic (Basis-Typ) | E4: =Matrix!E13 -> DE.N.SFH.03.Gen | F4: =Matrix!F13 -> DE.N.TH.03.Gen | G4: =Matrix!G13 -> DE.N.MFH.03.Gen | H4: =Matrix!H13 -> DE.N.AB.03.Gen | I4: =Matrix!J13 -> DE | J4: =Matrix!K13 -> N | K4: =Matrix!L13 -> National | L4: =Matrix!M13 -> nicht regional spezifiziert | M4: =Matrix!N13 -> 3 | N4: =Matrix!O13 -> 1919 | O4: =Matrix!P13 -> 1948 | P4: =Matrix!Q13 -> Gen | ... T4: =Matrix!U13 -> 0 | U4: =Matrix!W13 -> ReEx.001 | V4: =Matrix!X13 -> ReEx.001 | W4: =Matrix!Y13 -> ReEx.001 | X4: =Matrix!Z13 -> ReEx.001 | Y4: C | Z4: ="EFH_"&$Y4 -> EFH_C | AA4: ="RH_"&$Y4 -> RH_C | AB4: ="MFH_"&$Y4 -> MFH_C | AC4: ="GMH_"&$Y4 -> GMH_C | AD4: 45751
A5: =Matrix!A14 -> 4 | B5: =Matrix!B14 -> National (nicht regional spezifiziert) | C5: =Matrix!C14 -> 1949 ... 1957 | D5: =Matrix!D14 -> Generic (Basis-Typ) | E5: =Matrix!E14 -> DE.N.SFH.04.Gen | F5: =Matrix!F14 -> DE.N.TH.04.Gen | G5: =Matrix!G14 -> DE.N.MFH.04.Gen | H5: =Matrix!H14 -> DE.N.AB.04.Gen | I5: =Matrix!J14 -> DE | J5: =Matrix!K14 -> N | K5: =Matrix!L14 -> National | L5: =Matrix!M14 -> nicht regional spezifiziert | M5: =Matrix!N14 -> 4 | N5: =Matrix!O14 -> 1949 | O5: =Matrix!P14 -> 1957 | P5: =Matrix!Q14 -> Gen | ... T5: =Matrix!U14 -> 0 | U5: =Matrix!W14 -> ReEx.001 | V5: =Matrix!X14 -> ReEx.001 | W5: =Matrix!Y14 -> ReEx.001 | X5: =Matrix!Z14 -> ReEx.001 | Y5: D | Z5: ="EFH_"&$Y5 -> EFH_D | AA5: ="RH_"&$Y5 -> RH_D | AB5: ="MFH_"&$Y5 -> MFH_D | AC5: ="GMH_"&$Y5 -> GMH_D | AD5: 45751
A6: =Matrix!A15 -> 5 | B6: =Matrix!B15 -> National (nicht regional spezifiziert) | C6: =Matrix!C15 -> 1958 ... 1968 | D6: =Matrix!D15 -> Generic (Basis-Typ) | E6: =Matrix!E15 -> DE.N.SFH.05.Gen | F6: =Matrix!F15 -> DE.N.TH.05.Gen | G6: =Matrix!G15 -> DE.N.MFH.05.Gen | H6: =Matrix!H15 -> DE.N.AB.05.Gen | I6: =Matrix!J15 -> DE | J6: =Matrix!K15 -> N | K6: =Matrix!L15 -> National | L6: =Matrix!M15 -> nicht regional spezifiziert | M6: =Matrix!N15 -> 5 | N6: =Matrix!O15 -> 1958 | O6: =Matrix!P15 -> 1968 | P6: =Matrix!Q15 -> Gen | ... T6: =Matrix!U15 -> 0 | U6: =Matrix!W15 -> ReEx.001 | V6: =Matrix!X15 -> ReEx.001 | W6: =Matrix!Y15 -> ReEx.001 | X6: =Matrix!Z15 -> ReEx.001 | Y6: E | Z6: ="EFH_"&$Y6 -> EFH_E | AA6: ="RH_"&$Y6 -> RH_E | AB6: ="MFH_"&$Y6 -> MFH_E | AC6: ="GMH_"&$Y6 -> GMH_E | AD6: 45751
A7: =Matrix!A16 -> 6 | B7: =Matrix!B16 -> National (nicht regional spezifiziert) | C7: =Matrix!C16 -> 1969 ... 1978 | D7: =Matrix!D16 -> Generic (Basis-Typ) | E7: =Matrix!E16 -> DE.N.SFH.06.Gen | F7: =Matrix!F16 -> DE.N.TH.06.Gen | G7: =Matrix!G16 -> DE.N.MFH.06.Gen | H7: =Matrix!H16 -> DE.N.AB.06.Gen | I7: =Matrix!J16 -> DE | J7: =Matrix!K16 -> N | K7: =Matrix!L16 -> National | L7: =Matrix!M16 -> nicht regional spezifiziert | M7: =Matrix!N16 -> 6 | N7: =Matrix!O16 -> 1969 | O7: =Matrix!P16 -> 1978 | P7: =Matrix!Q16 -> Gen | ... T7: =Matrix!U16 -> 0 | U7: =Matrix!W16 -> ReEx.001 | V7: =Matrix!X16 -> ReEx.001 | W7: =Matrix!Y16 -> ReEx.001 | X7: =Matrix!Z16 -> ReEx.001 | Y7: F | Z7: ="EFH_"&$Y7 -> EFH_F | AA7: ="RH_"&$Y7 -> RH_F | AB7: ="MFH_"&$Y7 -> MFH_F | AC7: ="GMH_"&$Y7 -> GMH_F | AD7: 45751
A8: =Matrix!A17 -> 7 | B8: =Matrix!B17 -> National (nicht regional spezifiziert) | C8: =Matrix!C17 -> 1979 ... 1983 | D8: =Matrix!D17 -> Generic (Basis-Typ) | E8: =Matrix!E17 -> DE.N.SFH.07.Gen | F8: =Matrix!F17 -> DE.N.TH.07.Gen | G8: =Matrix!G17 -> DE.N.MFH.07.Gen | H8: =Matrix!H17 | I8: =Matrix!J17 -> DE | J8: =Matrix!K17 -> N | K8: =Matrix!L17 -> National | L8: =Matrix!M17 -> nicht regional spezifiziert | M8: =Matrix!N17 -> 7 | N8: =Matrix!O17 -> 1979 | O8: =Matrix!P17 -> 1983 | P8: =Matrix!Q17 -> Gen | ... T8: =Matrix!U17 -> 0 | U8: =Matrix!W17 -> ReEx.001 | V8: =Matrix!X17 -> ReEx.001 | W8: =Matrix!Y17 -> ReEx.001 | X8: =Matrix!Z17 -> 0 | Y8: G | Z8: ="EFH_"&$Y8 -> EFH_G | AA8: ="RH_"&$Y8 -> RH_G | AB8: ="MFH_"&$Y8 -> MFH_G | AC8: ="GMH_"&$Y8 -> GMH_G | AD8: 45751
A9: =Matrix!A18 -> 8 | B9: =Matrix!B18 -> National (nicht regional spezifiziert) | C9: =Matrix!C18 -> 1984 ... 1994 | D9: =Matrix!D18 -> Generic (Basis-Typ) | E9: =Matrix!E18 -> DE.N.SFH.08.Gen | F9: =Matrix!F18 -> DE.N.TH.08.Gen | G9: =Matrix!G18 -> DE.N.MFH.08.Gen | H9: =Matrix!H18 | I9: =Matrix!J18 -> DE | J9: =Matrix!K18 -> N | K9: =Matrix!L18 -> National | L9: =Matrix!M18 -> nicht regional spezifiziert | M9: =Matrix!N18 -> 8 | N9: =Matrix!O18 -> 1984 | O9: =Matrix!P18 -> 1994 | P9: =Matrix!Q18 -> Gen | ... T9: =Matrix!U18 -> 0 | U9: =Matrix!W18 -> ReEx.001 | V9: =Matrix!X18 -> ReEx.001 | W9: =Matrix!Y18 -> ReEx.001 | X9: =Matrix!Z18 -> 0 | Y9: H | Z9: ="EFH_"&$Y9 -> EFH_H | AA9: ="RH_"&$Y9 -> RH_H | AB9: ="MFH_"&$Y9 -> MFH_H | AC9: ="GMH_"&$Y9 -> GMH_H | AD9: 45751
A10: =Matrix!A19 -> 9 | B10: =Matrix!B19 -> National (nicht regional spezifiziert) | C10: =Matrix!C19 -> 1995 ... 2001 | D10: =Matrix!D19 -> Generic (Basis-Typ) | E10: =Matrix!E19 -> DE.N.SFH.09.Gen | F10: =Matrix!F19 -> DE.N.TH.09.Gen | G10: =Matrix!G19 -> DE.N.MFH.09.Gen | H10: =Matrix!H19 | I10: =Matrix!J19 -> DE | J10: =Matrix!K19 -> N | K10: =Matrix!L19 -> National | L10: =Matrix!M19 -> nicht regional spezifiziert | M10: =Matrix!N19 -> 9 | N10: =Matrix!O19 -> 1995 | O10: =Matrix!P19 -> 2001 | P10: =Matrix!Q19 -> Gen | ... T10: =Matrix!U19 -> 0 | U10: =Matrix!W19 -> ReEx.001 | V10: =Matrix!X19 -> ReEx.001 | W10: =Matrix!Y19 -> ReEx.001 | X10: =Matrix!Z19 -> 0 | Y10: I | Z10: ="EFH_"&$Y10 -> EFH_I | AA10: ="RH_"&$Y10 -> RH_I | AB10: ="MFH_"&$Y10 -> MFH_I | AC10: ="GMH_"&$Y10 -> GMH_I | AD10: 45751
A11: =Matrix!A20 -> 10 | B11: =Matrix!B20 -> National (nicht regional spezifiziert) | C11: =Matrix!C20 -> 2002 ... 2009 | D11: =Matrix!D20 -> Generic (Basis-Typ) | E11: =Matrix!E20 -> DE.N.SFH.10.Gen | F11: =Matrix!F20 -> DE.N.TH.10.Gen | G11: =Matrix!G20 -> DE.N.MFH.10.Gen | H11: =Matrix!H20 | I11: =Matrix!J20 -> DE | J11: =Matrix!K20 -> N | K11: =Matrix!L20 -> National | L11: =Matrix!M20 -> nicht regional spezifiziert | M11: =Matrix!N20 -> 10 | N11: =Matrix!O20 -> 2002 | O11: =Matrix!P20 -> 2009 | P11: =Matrix!Q20 -> Gen | ... T11: =Matrix!U20 -> 0 | U11: =Matrix!W20 -> ReEx.001 | V11: =Matrix!X20 -> ReEx.001 | W11: =Matrix!Y20 -> ReEx.001 | X11: =Matrix!Z20 -> 0 | Y11: J | Z11: ="EFH_"&$Y11 -> EFH_J | AA11: ="RH_"&$Y11 -> RH_J | AB11: ="MFH_"&$Y11 -> MFH_J | AC11: ="GMH_"&$Y11 -> GMH_J | AD11: 45751
A12: =Matrix!A21 -> 11 | B12: =Matrix!B21 -> National (nicht regional spezifiziert) | C12: =Matrix!C21 -> 2010 ... 2015 | D12: =Matrix!D21 -> Generic (Basis-Typ) | E12: =Matrix!E21 -> DE.N.SFH.11.Gen | F12: =Matrix!F21 -> DE.N.TH.11.Gen | G12: =Matrix!G21 -> DE.N.MFH.11.Gen | H12: =Matrix!H21 | I12: =Matrix!J21 -> DE | J12: =Matrix!K21 -> N | K12: =Matrix!L21 -> National | L12: =Matrix!M21 -> nicht regional spezifiziert | M12: =Matrix!N21 -> 11 | N12: =Matrix!O21 -> 2010 | O12: =Matrix!P21 -> 2015 | P12: =Matrix!Q21 -> Gen | ... T12: =Matrix!U21 -> 0 | U12: =Matrix!W21 -> ReEx.001 | V12: =Matrix!X21 -> ReEx.001 | W12: =Matrix!Y21 -> ReEx.001 | X12: =Matrix!Z21 -> 0 | Y12: K | Z12: ="EFH_"&$Y12 -> EFH_K | AA12: ="RH_"&$Y12 -> RH_K | AB12: ="MFH_"&$Y12 -> MFH_K | AC12: ="GMH_"&$Y12 -> GMH_K | AD12: 45751
A13: =Matrix!A22 -> 12 | B13: =Matrix!B22 -> National (nicht regional spezifiziert) | C13: 2016 … 2022 | D13: =Matrix!D22 -> Generic (Basis-Typ) | E13: =Matrix!E22 -> DE.N.SFH.12.Gen | F13: =Matrix!F22 -> DE.N.TH.12.Gen | G13: =Matrix!G22 -> DE.N.MFH.12.Gen | H13: =Matrix!H22 | I13: =Matrix!J22 -> DE | J13: =Matrix!K22 -> N | K13: =Matrix!L22 -> National | L13: =Matrix!M22 -> nicht regional spezifiziert | M13: =Matrix!N22 -> 12 | N13: =Matrix!O22 -> 2016 | O13: 2022 | P13: =Matrix!Q22 -> Gen | Q13: =Matrix!R22 -> Generic | R13: =Matrix!S22 -> Basis-Typ | S13: =Matrix!T22 -> 0 | T13: =Matrix!U22 -> 0 | U13: =Matrix!W22 -> ReEx.001 | V13: =Matrix!X22 -> ReEx.001 | W13: =Matrix!Y22 -> ReEx.001 | X13: =Matrix!Z22 -> 0 | Y13: L | Z13: ="EFH_"&$Y13 -> EFH_L | AA13: ="RH_"&$Y13 -> RH_L | AB13: ="MFH_"&$Y13 -> MFH_L | AC13: ="GMH_"&$Y13 -> GMH_L | AD13: 45751
A14: 13 | B14: National (nicht regional spezifiziert) | C14: 2023 ... | D14: Generic (Basis-Typ) | E14: DE.N.SFH.13.Gen | F14: DE.N.TH.13.Gen | G14: DE.N.MFH.13.Gen | I14: DE | J14: N | K14: National | L14: nicht regional spezifiziert | M14: 13 | N14: 2023 | O14: 9999 | P14: Gen | Q14: Generic | R14: Basis-Typ | S14: 0 | T14: 0 | U14: ReEx.001 | V14: ReEx.001 | W14: ReEx.001 | X14: 0 | Y14: M | Z14: ="EFH_"&$Y14 -> EFH_M | AA14: ="RH_"&$Y14 -> RH_M | AB14: ="MFH_"&$Y14 -> MFH_M | AC14: ="GMH_"&$Y14 -> GMH_M | AD14: 45751
A15: 14 | B15: =Matrix!B23 -> National (nicht regional spezifiziert) | C15: =Matrix!C23 -> 1969 ... 1978 | D15: =Matrix!D23 -> Light Frame Structure (Fertighaus / Leichtbau) | E15: =Matrix!E23 -> DE.N.SFH.06.LightFrame | F15: =Matrix!F23 | G15: =Matrix!G23 | H15: =Matrix!H23 | I15: =Matrix!J23 -> DE | J15: =Matrix!K23 -> N | K15: =Matrix!L23 -> National | L15: =Matrix!M23 -> nicht regional spezifiziert | M15: =Matrix!N23 -> 6 | N15: =Matrix!O23 -> 1969 | O15: =Matrix!P23 -> 1978 | P15: =Matrix!Q23 -> LightFrame | ... T15: =Matrix!U23 -> 0 | U15: =Matrix!W23 -> ReEx.001 | V15: =Matrix!X23 -> 0 | W15: =Matrix!Y23 -> 0 | X15: =Matrix!Z23 -> 0 | Y15: F | Z15: EFH_F/F | AD15: 45751
A16: 15 | B16: =Matrix!B24 -> National (nicht regional spezifiziert) | C16: =Matrix!C24 -> 1958 ... 1968 | D16: =Matrix!D24 -> High-Rise Building (Hochhaus) | E16: =Matrix!E24 | F16: =Matrix!F24 | G16: =Matrix!G24 | H16: =Matrix!H24 -> DE.N.AB.05.HR | I16: =Matrix!J24 -> DE | J16: =Matrix!K24 -> N | K16: =Matrix!L24 -> National | L16: =Matrix!M24 -> nicht regional spezifiziert | M16: =Matrix!N24 -> 5 | N16: =Matrix!O24 -> 1958 | O16: =Matrix!P24 -> 1968 | P16: =Matrix!Q24 -> HR | ... T16: =Matrix!U24 -> 0 | U16: =Matrix!W24 -> 0 | V16: =Matrix!X24 -> 0 | W16: =Matrix!Y24 -> 0 | X16: =Matrix!Z24 -> ReEx.001 | Y16: E | AC16: HH_E | AD16: 45751
A17: 16 | B17: =Matrix!B25 -> National (nicht regional spezifiziert) | C17: =Matrix!C25 -> 1969 ... 1978 | D17: =Matrix!D25 -> High-Rise Building (Hochhaus) | E17: =Matrix!E25 | F17: =Matrix!F25 | G17: =Matrix!G25 | H17: =Matrix!H25 -> DE.N.AB.06.HR | I17: =Matrix!J25 -> DE | J17: =Matrix!K25 -> N | K17: =Matrix!L25 -> National | L17: =Matrix!M25 -> nicht regional spezifiziert | M17: =Matrix!N25 -> 6 | N17: =Matrix!O25 -> 1969 | O17: =Matrix!P25 -> 1978 | P17: =Matrix!Q25 -> HR | ... T17: =Matrix!U25 -> 0 | U17: =Matrix!W25 -> 0 | V17: =Matrix!X25 -> 0 | W17: =Matrix!Y25 -> 0 | X17: =Matrix!Z25 -> ReEx.001 | Y17: F | AC17: HH_F | AD17: 45751
A18: 17 | B18: =Matrix!B26 -> Eastern Germany / former GDR (neue Bundesländer) | C18: =Matrix!C26 -> 1949 ... 1957 | D18: =Matrix!D26 -> Generic (Basis-Typ) | E18: =Matrix!E26 | F18: =Matrix!F26 | G18: =Matrix!G26 -> DE.East.MFH.04.Gen | H18: =Matrix!H26 | I18: =Matrix!J26 -> DE | J18: =Matrix!K26 -> East | K18: =Matrix!L26 -> Eastern Germany / former GDR | L18: =Matrix!M26 -> neue Bundesländer | M18: =Matrix!N26 -> 4 | N18: =Matrix!O26 -> 1949 | O18: =Matrix!P26 -> 1957 | P18: =Matrix!Q26 -> Gen | ... T18: =Matrix!U26 -> 0 | U18: =Matrix!W26 -> 0 | V18: =Matrix!X26 -> 0 | W18: =Matrix!Y26 -> ReEx.001 | X18: =Matrix!Z26 -> 0 | Y18: D | AB18: NBL_MFH_D | AD18: 45751
A19: 18 | B19: =Matrix!B27 -> Eastern Germany / former GDR (neue Bundesländer) | C19: =Matrix!C27 -> 1958 ... 1968 | D19: =Matrix!D27 -> Generic (Basis-Typ) | E19: =Matrix!E27 | F19: =Matrix!F27 | G19: =Matrix!G27 -> DE.East.MFH.05.Gen | H19: =Matrix!H27 | I19: =Matrix!J27 -> DE | J19: =Matrix!K27 -> East | K19: =Matrix!L27 -> Eastern Germany / former GDR | L19: =Matrix!M27 -> neue Bundesländer | M19: =Matrix!N27 -> 5 | N19: =Matrix!O27 -> 1958 | O19: =Matrix!P27 -> 1968 | P19: =Matrix!Q27 -> Gen | ... T19: =Matrix!U27 -> 0 | U19: =Matrix!W27 -> 0 | V19: =Matrix!X27 -> 0 | W19: =Matrix!Y27 -> ReEx.001 | X19: =Matrix!Z27 -> 0 | Y19: E | AB19: NBL_MFH_E | AD19: 45751
A20: 19 | B20: =Matrix!B28 -> Eastern Germany / former GDR (neue Bundesländer) | C20: =Matrix!C28 -> 1969 ... 1978 | D20: =Matrix!D28 -> Generic (Basis-Typ) | E20: =Matrix!E28 | F20: =Matrix!F28 | G20: =Matrix!G28 | H20: =Matrix!H28 -> DE.East.AB.06.Gen | I20: =Matrix!J28 -> DE | J20: =Matrix!K28 -> East | K20: =Matrix!L28 -> Eastern Germany / former GDR | L20: =Matrix!M28 -> neue Bundesländer | M20: =Matrix!N28 -> 6 | N20: =Matrix!O28 -> 1969 | O20: =Matrix!P28 -> 1978 | P20: =Matrix!Q28 -> Gen | ... T20: =Matrix!U28 -> 0 | U20: =Matrix!W28 -> 0 | V20: =Matrix!X28 -> 0 | W20: =Matrix!Y28 -> 0 | X20: =Matrix!Z28 -> ReEx.001 | Y20: F | AC20: NBL_GMH_F | AD20: 45751
A21: 20 | B21: =Matrix!B29 -> Eastern Germany / former GDR (neue Bundesländer) | C21: =Matrix!C29 -> 1979 ... 1983 | D21: =Matrix!D29 -> Generic (Basis-Typ) | E21: =Matrix!E29 | F21: =Matrix!F29 | G21: =Matrix!G29 | H21: =Matrix!H29 -> DE.East.AB.07.Gen | I21: =Matrix!J29 -> DE | J21: =Matrix!K29 -> East | K21: =Matrix!L29 -> Eastern Germany / former GDR | L21: =Matrix!M29 -> neue Bundesländer | M21: =Matrix!N29 -> 7 | N21: =Matrix!O29 -> 1979 | O21: =Matrix!P29 -> 1983 | P21: =Matrix!Q29 -> Gen | ... T21: =Matrix!U29 -> 0 | U21: =Matrix!W29 -> 0 | V21: =Matrix!X29 -> 0 | W21: =Matrix!Y29 -> 0 | X21: =Matrix!Z29 -> ReEx.001 | Y21: G | AC21: NBL_GMH_G | AD21: 45751
A22: 21 | B22: =Matrix!B30 -> Eastern Germany / former GDR (neue Bundesländer) | C22: =Matrix!C30 -> 1984 ... 1994 | D22: =Matrix!D30 -> Generic (Basis-Typ) | E22: =Matrix!E30 | F22: =Matrix!F30 | G22: =Matrix!G30 | H22: =Matrix!H30 -> DE.East.AB.08.Gen | I22: =Matrix!J30 -> DE | J22: =Matrix!K30 -> East | K22: =Matrix!L30 -> Eastern Germany / former GDR | L22: =Matrix!M30 -> neue Bundesländer | M22: =Matrix!N30 -> 8 | N22: =Matrix!O30 -> 1984 | O22: =Matrix!P30 -> 1994 | P22: =Matrix!Q30 -> Gen | ... T22: =Matrix!U30 -> 0 | U22: =Matrix!W30 -> 0 | V22: =Matrix!X30 -> 0 | W22: =Matrix!Y30 -> 0 | X22: =Matrix!Z30 -> ReEx.001 | Y22: H | AC22: NBL_GMH_H | AD22: 45751
A23: 22 | B23: =Matrix!B31 -> Eastern Germany / former GDR (neue Bundesländer) | C23: =Matrix!C31 -> 1969 ... 1978 | D23: =Matrix!D31 -> High-Rise Building (Hochhaus) | E23: =Matrix!E31 | F23: =Matrix!F31 | G23: =Matrix!G31 | H23: =Matrix!H31 -> DE.East.AB.06.HR | I23: =Matrix!J31 -> DE | J23: =Matrix!K31 -> East | K23: =Matrix!L31 -> Eastern Germany / former GDR | L23: =Matrix!M31 -> neue Bundesländer | M23: =Matrix!N31 -> 6 | N23: =Matrix!O31 -> 1969 | O23: =Matrix!P31 -> 1978 | P23: =Matrix!Q31 -> HR | ... T23: =Matrix!U31 -> 0 | U23: =Matrix!W31 -> 0 | V23: =Matrix!X31 -> 0 | W23: =Matrix!Y31 -> 0 | X23: =Matrix!Z31 -> ReEx.001 | Y23: F | AC23: NBL_HH_F | AD23: 45751
A24: 23 | B24: =Matrix!B32 -> Eastern Germany / former GDR (neue Bundesländer) | C24: =Matrix!C32 -> 1979 ... 1983 | D24: =Matrix!D32 -> High-Rise Building (Hochhaus) | E24: =Matrix!E32 | F24: =Matrix!F32 | G24: =Matrix!G32 | H24: =Matrix!H32 -> DE.East.AB.07.HR | I24: =Matrix!J32 -> DE | J24: =Matrix!K32 -> East | K24: =Matrix!L32 -> Eastern Germany / former GDR | L24: =Matrix!M32 -> neue Bundesländer | M24: =Matrix!N32 -> 7 | N24: =Matrix!O32 -> 1979 | O24: =Matrix!P32 -> 1983 | P24: =Matrix!Q32 -> HR | ... T24: =Matrix!U32 -> 0 | U24: =Matrix!W32 -> 0 | V24: =Matrix!X32 -> 0 | W24: =Matrix!Y32 -> 0 | X24: =Matrix!Z32 -> ReEx.001 | Y24: G | AC24: NBL_HH_G | AD24: 45751
A25: 24 | B25: --- | C25: --- | D25: --- | E25: --- | F25: --- | G25: --- | H25: --- | I25: --- | J25: --- | K25: --- | L25: --- | M25: --- | N25: --- | O25: --- | P25: --- | Q25: --- | R25: --- | S25: --- | T25: --- | U25: --- | V25: --- | W25: --- | X25: --- | Y25: --- | Z25: --- | AA25: --- | AB25: --- | AC25: --- | AD25: 45800

Sheet Matrix
A1: Index_Row | B1: Display_Region | C1: Display_ConstructionYearClass | D1: Display_AdditionalParameter | E1: Code_BuildingType_Column1 | F1: Code_BuildingType_Column2 | G1: Code_BuildingType_Column3 | H1: Code_BuildingType_Column4 | J1: Code_Country | K1: Code_TypologyRegion | L1: Name_TypologyRegion | M1: Name_National_TypologyRegion | N1: Number_ConstructionYearClass | O1: ConstructionYearClass_FirstYear | P1: ConstructionYearClass_LastYear | Q1: Code_AdditionalParameter | R1: Name_AdditionalParameter | S1: Name_AdditionalParameter_National | T1: Comment | U1: Note_DataBaseAdmin | W1: Suffix_Building_Column1 | X1: Suffix_Building_Column2 | Y1: Suffix_Building_Column3 | Z1: Suffix_Building_Column4 | AB1: Status_Dataset_Column1 | AC1: Status_Dataset_Column2 | AD1: Status_Dataset_Column3 | AE1: Status_Dataset_Column4 | AG1: Status_BuildingType_Column1 | AH1: Status_BuildingType_Column2 | AI1: Status_BuildingType_Column3 | AJ1: Status_BuildingType_Column4
A7: Building Type Matrix | AN7: Evaluation
E8: Germany | AB8: 1 = dataset available | AG8: number is calculated automatically | AN8: all | AO8: all | AP8: thereof "Gen" | AQ8: thereof "Gen"
B9: Region | C9: Construction Year Class | D9: Additional Classification | E9: SFH | F9: TH | G9: MFH | H9: AB | AB9: if not available pictures will appear light grey after import | AG9: (relevant for colour of matrix cells) | AN9: SUH | AO9: MUH | AP9: SUH | AQ9: MUH
E10: Single-Family House | F10: Terraced House | G10: Multi-Family House | H10: Apartment Block | AM10: Sum | AN10: =SUM(AN11:AN5001) -> 24 | AO10: =SUM(AO11:AO5001) -> 26 | AP10: =SUM(AP11:AP5001) -> 23 | AQ10: =SUM(AQ11:AQ5001) -> 22
A11: =OFFSET(A11,-1,0)+1 -> 1 | B11: =CONCATENATE(L11,IF(AND(M11<>L11,M11<>"")," ("&M11&")","")) -> National (nicht regional spezifiziert) | C11: =IF(AND(ISNUMBER(O11),O11>0),O11,"")&" ... "&IF(AND(ISNUMBER(P11),P11<9999),P11,"") -> ... 1859 | D11: =CONCATENATE(R11,IF(AND(S11<>R11,S11<>"")," ("&S11&")","")) -> Generic (Basis-Typ) | E11: =IF(W11<>"",$J11&"."&$K11&"."&E$9&"."&TEXT($N11,"00")&"."&$Q11,"") -> DE.N.SFH.01.Gen | F11: =IF(X11<>"",$J11&"."&$K11&"."&F$9&"."&TEXT($N11,"00")&"."&$Q11,"") | G11: =IF(Y11<>"",$J11&"."&$K11&"."&G$9&"."&TEXT($N11,"00")&"."&$Q11,"") -> DE.N.MFH.01.Gen | H11: =IF(Z11<>"",$J11&"."&$K11&"."&H$9&"."&TEXT($N11,"00")&"."&$Q11,"") | J11: DE | K11: N | L11: National | M11: nicht regional spezifiziert | N11: 1 | O11: 0 | P11: 1859 | Q11: Gen | R11: Generic | S11: Basis-Typ | W11: ReEx.001 | Y11: ReEx.001 | AB11: 1 | AC11: 1 | AD11: 1 | AE11: 1 | AG11: =IF(AND($K11="N",$Q11="Gen"),1,IF(OR($K11<>$K10,$Q11<>$Q10),MOD(AG10+1,2)+2,AG10)) -> 1 | AH11: =IF(AND($K11="N",$Q11="Gen"),1,IF(OR($K11<>$K10,$Q11<>$Q10),MOD(AH10+1,2)+2,AH10)) -> 1 | AI11: =IF(AND($K11="N",$Q11="Gen"),1,IF(OR($K11<>$K10,$Q11<>$Q10),MOD(AI10+1,2)+2,AI10)) -> 1 | AJ11: =IF(AND($K11="N",$Q11="Gen"),1,IF(OR($K11<>$K10,$Q11<>$Q10),MOD(AJ10+1,2)+2,AJ10)) -> 1 | AN11: =IF($K11<>"",2-COUNTBLANK($E11:$F11),0) -> 1 | AO11: =IF($K11<>"",2-COUNTBLANK($G11:$H11),0) -> 1 | AP11: =IF(AND($K11<>"",$Q11="Gen"),2-COUNTBLANK($E11:$F11),0) -> 1 | AQ11: =IF(AND($K11<>"",$Q11="Gen"),2-COUNTBLANK($G11:$H11),0) -> 1
A12: =OFFSET(A12,-1,0)+1 -> 2 | B12: =CONCATENATE(L12,IF(AND(M12<>L12,M12<>"")," ("&M12&")","")) -> National (nicht regional spezifiziert) | C12: =IF(AND(ISNUMBER(O12),O12>0),O12,"")&" ... "&IF(AND(ISNUMBER(P12),P12<9999),P12,"") -> 1860 ... 1918 | D12: =CONCATENATE(R12,IF(AND(S12<>R12,S12<>"")," ("&S12&")","")) -> Generic (Basis-Typ) | E12: =IF(W12<>"",$J12&"."&$K12&"."&E$9&"."&TEXT($N12,"00")&"."&$Q12,"") -> DE.N.SFH.02.Gen | F12: =IF(X12<>"",$J12&"."&$K12&"."&F$9&"."&TEXT($N12,"00")&"."&$Q12,"") -> DE.N.TH.02.Gen | G12: =IF(Y12<>"",$J12&"."&$K12&"."&G$9&"."&TEXT($N12,"00")&"."&$Q12,"") -> DE.N.MFH.02.Gen | H12: =IF(Z12<>"",$J12&"."&$K12&"."&H$9&"."&TEXT($N12,"00")&"."&$Q12,"") -> DE.N.AB.02.Gen | J12: =OFFSET(J12,-1,0) -> DE | K12: N | L12: National | M12: nicht regional spezifiziert | N12: 2 | O12: 1860 | P12: 1918 | Q12: Gen | R12: Generic | S12: Basis-Typ | W12: ReEx.001 | X12: ReEx.001 | Y12: ReEx.001 | Z12: ReEx.001 | AB12: 1 | AC12: 1 | AD12: 1 | AE12: 1 | AG12: =IF(AND($K12="N",$Q12="Gen"),1,IF(OR($K12<>$K11,$Q12<>$Q11),MOD(AG11+1,2)+2,AG11)) -> 1 | AH12: =IF(AND($K12="N",$Q12="Gen"),1,IF(OR($K12<>$K11,$Q12<>$Q11),MOD(AH11+1,2)+2,AH11)) -> 1 | AI12: =IF(AND($K12="N",$Q12="Gen"),1,IF(OR($K12<>$K11,$Q12<>$Q11),MOD(AI11+1,2)+2,AI11)) -> 1 | AJ12: =IF(AND($K12="N",$Q12="Gen"),1,IF(OR($K12<>$K11,$Q12<>$Q11),MOD(AJ11+1,2)+2,AJ11)) -> 1 | AN12: =IF($K12<>"",2-COUNTBLANK($E12:$F12),0) -> 2 | AO12: =IF($K12<>"",2-COUNTBLANK($G12:$H12),0) -> 2 | AP12: =IF(AND($K12<>"",$Q12="Gen"),2-COUNTBLANK($E12:$F12),0) -> 2 | AQ12: =IF(AND($K12<>"",$Q12="Gen"),2-COUNTBLANK($G12:$H12),0) -> 2
A13: =OFFSET(A13,-1,0)+1 -> 3 | B13: =CONCATENATE(L13,IF(AND(M13<>L13,M13<>"")," ("&M13&")","")) -> National (nicht regional spezifiziert) | C13: =IF(AND(ISNUMBER(O13),O13>0),O13,"")&" ... "&IF(AND(ISNUMBER(P13),P13<9999),P13,"") -> 1919 ... 1948 | D13: =CONCATENATE(R13,IF(AND(S13<>R13,S13<>"")," ("&S13&")","")) -> Generic (Basis-Typ) | E13: =IF(W13<>"",$J13&"."&$K13&"."&E$9&"."&TEXT($N13,"00")&"."&$Q13,"") -> DE.N.SFH.03.Gen | F13: =IF(X13<>"",$J13&"."&$K13&"."&F$9&"."&TEXT($N13,"00")&"."&$Q13,"") -> DE.N.TH.03.Gen | G13: =IF(Y13<>"",$J13&"."&$K13&"."&G$9&"."&TEXT($N13,"00")&"."&$Q13,"") -> DE.N.MFH.03.Gen | H13: =IF(Z13<>"",$J13&"."&$K13&"."&H$9&"."&TEXT($N13,"00")&"."&$Q13,"") -> DE.N.AB.03.Gen | J13: =OFFSET(J13,-1,0) -> DE | K13: N | L13: National | M13: nicht regional spezifiziert | N13: 3 | O13: 1919 | P13: 1948 | Q13: Gen | R13: Generic | S13: Basis-Typ | W13: ReEx.001 | X13: ReEx.001 | Y13: ReEx.001 | Z13: ReEx.001 | AB13: 1 | AC13: 1 | AD13: 1 | AE13: 1 | AG13: =IF(AND($K13="N",$Q13="Gen"),1,IF(OR($K13<>$K12,$Q13<>$Q12),MOD(AG12+1,2)+2,AG12)) -> 1 | AH13: =IF(AND($K13="N",$Q13="Gen"),1,IF(OR($K13<>$K12,$Q13<>$Q12),MOD(AH12+1,2)+2,AH12)) -> 1 | AI13: =IF(AND($K13="N",$Q13="Gen"),1,IF(OR($K13<>$K12,$Q13<>$Q12),MOD(AI12+1,2)+2,AI12)) -> 1 | AJ13: =IF(AND($K13="N",$Q13="Gen"),1,IF(OR($K13<>$K12,$Q13<>$Q12),MOD(AJ12+1,2)+2,AJ12)) -> 1 | AN13: =IF($K13<>"",2-COUNTBLANK($E13:$F13),0) -> 2 | AO13: =IF($K13<>"",2-COUNTBLANK($G13:$H13),0) -> 2 | AP13: =IF(AND($K13<>"",$Q13="Gen"),2-COUNTBLANK($E13:$F13),0) -> 2 | AQ13: =IF(AND($K13<>"",$Q13="Gen"),2-COUNTBLANK($G13:$H13),0) -> 2
A14: =OFFSET(A14,-1,0)+1 -> 4 | B14: =CONCATENATE(L14,IF(AND(M14<>L14,M14<>"")," ("&M14&")","")) -> National (nicht regional spezifiziert) | C14: =IF(AND(ISNUMBER(O14),O14>0),O14,"")&" ... "&IF(AND(ISNUMBER(P14),P14<9999),P14,"") -> 1949 ... 1957 | D14: =CONCATENATE(R14,IF(AND(S14<>R14,S14<>"")," ("&S14&")","")) -> Generic (Basis-Typ) | E14: =IF(W14<>"",$J14&"."&$K14&"."&E$9&"."&TEXT($N14,"00")&"."&$Q14,"") -> DE.N.SFH.04.Gen | F14: =IF(X14<>"",$J14&"."&$K14&"."&F$9&"."&TEXT($N14,"00")&"."&$Q14,"") -> DE.N.TH.04.Gen | G14: =IF(Y14<>"",$J14&"."&$K14&"."&G$9&"."&TEXT($N14,"00")&"."&$Q14,"") -> DE.N.MFH.04.Gen | H14: =IF(Z14<>"",$J14&"."&$K14&"."&H$9&"."&TEXT($N14,"00")&"."&$Q14,"") -> DE.N.AB.04.Gen | J14: =OFFSET(J14,-1,0) -> DE | K14: N | L14: National | M14: nicht regional spezifiziert | N14: 4 | O14: 1949 | P14: 1957 | Q14: Gen | R14: Generic | S14: Basis-Typ | W14: ReEx.001 | X14: ReEx.001 | Y14: ReEx.001 | Z14: ReEx.001 | AB14: 1 | AC14: 1 | AD14: 1 | AE14: 1 | AG14: =IF(AND($K14="N",$Q14="Gen"),1,IF(OR($K14<>$K13,$Q14<>$Q13),MOD(AG13+1,2)+2,AG13)) -> 1 | AH14: =IF(AND($K14="N",$Q14="Gen"),1,IF(OR($K14<>$K13,$Q14<>$Q13),MOD(AH13+1,2)+2,AH13)) -> 1 | AI14: =IF(AND($K14="N",$Q14="Gen"),1,IF(OR($K14<>$K13,$Q14<>$Q13),MOD(AI13+1,2)+2,AI13)) -> 1 | AJ14: =IF(AND($K14="N",$Q14="Gen"),1,IF(OR($K14<>$K13,$Q14<>$Q13),MOD(AJ13+1,2)+2,AJ13)) -> 1 | AN14: =IF($K14<>"",2-COUNTBLANK($E14:$F14),0) -> 2 | AO14: =IF($K14<>"",2-COUNTBLANK($G14:$H14),0) -> 2 | AP14: =IF(AND($K14<>"",$Q14="Gen"),2-COUNTBLANK($E14:$F14),0) -> 2 | AQ14: =IF(AND($K14<>"",$Q14="Gen"),2-COUNTBLANK($G14:$H14),0) -> 2
A15: =OFFSET(A15,-1,0)+1 -> 5 | B15: =CONCATENATE(L15,IF(AND(M15<>L15,M15<>"")," ("&M15&")","")) -> National (nicht regional spezifiziert) | C15: =IF(AND(ISNUMBER(O15),O15>0),O15,"")&" ... "&IF(AND(ISNUMBER(P15),P15<9999),P15,"") -> 1958 ... 1968 | D15: =CONCATENATE(R15,IF(AND(S15<>R15,S15<>"")," ("&S15&")","")) -> Generic (Basis-Typ) | E15: =IF(W15<>"",$J15&"."&$K15&"."&E$9&"."&TEXT($N15,"00")&"."&$Q15,"") -> DE.N.SFH.05.Gen | F15: =IF(X15<>"",$J15&"."&$K15&"."&F$9&"."&TEXT($N15,"00")&"."&$Q15,"") -> DE.N.TH.05.Gen | G15: =IF(Y15<>"",$J15&"."&$K15&"."&G$9&"."&TEXT($N15,"00")&"."&$Q15,"") -> DE.N.MFH.05.Gen | H15: =IF(Z15<>"",$J15&"."&$K15&"."&H$9&"."&TEXT($N15,"00")&"."&$Q15,"") -> DE.N.AB.05.Gen | J15: =OFFSET(J15,-1,0) -> DE | K15: N | L15: National | M15: nicht regional spezifiziert | N15: 5 | O15: 1958 | P15: 1968 | Q15: Gen | R15: Generic | S15: Basis-Typ | W15: ReEx.001 | X15: ReEx.001 | Y15: ReEx.001 | Z15: ReEx.001 | AB15: 1 | AC15: 1 | AD15: 1 | AE15: 1 | AG15: =IF(AND($K15="N",$Q15="Gen"),1,IF(OR($K15<>$K14,$Q15<>$Q14),MOD(AG14+1,2)+2,AG14)) -> 1 | AH15: =IF(AND($K15="N",$Q15="Gen"),1,IF(OR($K15<>$K14,$Q15<>$Q14),MOD(AH14+1,2)+2,AH14)) -> 1 | AI15: =IF(AND($K15="N",$Q15="Gen"),1,IF(OR($K15<>$K14,$Q15<>$Q14),MOD(AI14+1,2)+2,AI14)) -> 1 | AJ15: =IF(AND($K15="N",$Q15="Gen"),1,IF(OR($K15<>$K14,$Q15<>$Q14),MOD(AJ14+1,2)+2,AJ14)) -> 1 | AN15: =IF($K15<>"",2-COUNTBLANK($E15:$F15),0) -> 2 | AO15: =IF($K15<>"",2-COUNTBLANK($G15:$H15),0) -> 2 | AP15: =IF(AND($K15<>"",$Q15="Gen"),2-COUNTBLANK($E15:$F15),0) -> 2 | AQ15: =IF(AND($K15<>"",$Q15="Gen"),2-COUNTBLANK($G15:$H15),0) -> 2
A16: =OFFSET(A16,-1,0)+1 -> 6 | B16: =CONCATENATE(L16,IF(AND(M16<>L16,M16<>"")," ("&M16&")","")) -> National (nicht regional spezifiziert) | C16: =IF(AND(ISNUMBER(O16),O16>0),O16,"")&" ... "&IF(AND(ISNUMBER(P16),P16<9999),P16,"") -> 1969 ... 1978 | D16: =CONCATENATE(R16,IF(AND(S16<>R16,S16<>"")," ("&S16&")","")) -> Generic (Basis-Typ) | E16: =IF(W16<>"",$J16&"."&$K16&"."&E$9&"."&TEXT($N16,"00")&"."&$Q16,"") -> DE.N.SFH.06.Gen | F16: =IF(X16<>"",$J16&"."&$K16&"."&F$9&"."&TEXT($N16,"00")&"."&$Q16,"") -> DE.N.TH.06.Gen | G16: =IF(Y16<>"",$J16&"."&$K16&"."&G$9&"."&TEXT($N16,"00")&"."&$Q16,"") -> DE.N.MFH.06.Gen | H16: =IF(Z16<>"",$J16&"."&$K16&"."&H$9&"."&TEXT($N16,"00")&"."&$Q16,"") -> DE.N.AB.06.Gen | J16: =OFFSET(J16,-1,0) -> DE | K16: N | L16: National | M16: nicht regional spezifiziert | N16: 6 | O16: 1969 | P16: 1978 | Q16: Gen | R16: Generic | S16: Basis-Typ | W16: ReEx.001 | X16: ReEx.001 | Y16: ReEx.001 | Z16: ReEx.001 | AB16: 1 | AC16: 1 | AD16: 1 | AE16: 1 | AG16: =IF(AND($K16="N",$Q16="Gen"),1,IF(OR($K16<>$K15,$Q16<>$Q15),MOD(AG15+1,2)+2,AG15)) -> 1 | AH16: =IF(AND($K16="N",$Q16="Gen"),1,IF(OR($K16<>$K15,$Q16<>$Q15),MOD(AH15+1,2)+2,AH15)) -> 1 | AI16: =IF(AND($K16="N",$Q16="Gen"),1,IF(OR($K16<>$K15,$Q16<>$Q15),MOD(AI15+1,2)+2,AI15)) -> 1 | AJ16: =IF(AND($K16="N",$Q16="Gen"),1,IF(OR($K16<>$K15,$Q16<>$Q15),MOD(AJ15+1,2)+2,AJ15)) -> 1 | AN16: =IF($K16<>"",2-COUNTBLANK($E16:$F16),0) -> 2 | AO16: =IF($K16<>"",2-COUNTBLANK($G16:$H16),0) -> 2 | AP16: =IF(AND($K16<>"",$Q16="Gen"),2-COUNTBLANK($E16:$F16),0) -> 2 | AQ16: =IF(AND($K16<>"",$Q16="Gen"),2-COUNTBLANK($G16:$H16),0) -> 2
A17: =OFFSET(A17,-1,0)+1 -> 7 | B17: =CONCATENATE(L17,IF(AND(M17<>L17,M17<>"")," ("&M17&")","")) -> National (nicht regional spezifiziert) | C17: =IF(AND(ISNUMBER(O17),O17>0),O17,"")&" ... "&IF(AND(ISNUMBER(P17),P17<9999),P17,"") -> 1979 ... 1983 | D17: =CONCATENATE(R17,IF(AND(S17<>R17,S17<>"")," ("&S17&")","")) -> Generic (Basis-Typ) | E17: =IF(W17<>"",$J17&"."&$K17&"."&E$9&"."&TEXT($N17,"00")&"."&$Q17,"") -> DE.N.SFH.07.Gen | F17: =IF(X17<>"",$J17&"."&$K17&"."&F$9&"."&TEXT($N17,"00")&"."&$Q17,"") -> DE.N.TH.07.Gen | G17: =IF(Y17<>"",$J17&"."&$K17&"."&G$9&"."&TEXT($N17,"00")&"."&$Q17,"") -> DE.N.MFH.07.Gen | H17: =IF(Z17<>"",$J17&"."&$K17&"."&H$9&"."&TEXT($N17,"00")&"."&$Q17,"") | J17: =OFFSET(J17,-1,0) -> DE | K17: N | L17: National | M17: nicht regional spezifiziert | N17: 7 | O17: 1979 | P17: 1983 | Q17: Gen | R17: Generic | S17: Basis-Typ | W17: ReEx.001 | X17: ReEx.001 | Y17: ReEx.001 | AB17: 1 | AC17: 1 | AD17: 1 | AE17: 1 | AG17: =IF(AND($K17="N",$Q17="Gen"),1,IF(OR($K17<>$K16,$Q17<>$Q16),MOD(AG16+1,2)+2,AG16)) -> 1 | AH17: =IF(AND($K17="N",$Q17="Gen"),1,IF(OR($K17<>$K16,$Q17<>$Q16),MOD(AH16+1,2)+2,AH16)) -> 1 | AI17: =IF(AND($K17="N",$Q17="Gen"),1,IF(OR($K17<>$K16,$Q17<>$Q16),MOD(AI16+1,2)+2,AI16)) -> 1 | AJ17: =IF(AND($K17="N",$Q17="Gen"),1,IF(OR($K17<>$K16,$Q17<>$Q16),MOD(AJ16+1,2)+2,AJ16)) -> 1 | AN17: =IF($K17<>"",2-COUNTBLANK($E17:$F17),0) -> 2 | AO17: =IF($K17<>"",2-COUNTBLANK($G17:$H17),0) -> 1 | AP17: =IF(AND($K17<>"",$Q17="Gen"),2-COUNTBLANK($E17:$F17),0) -> 2 | AQ17: =IF(AND($K17<>"",$Q17="Gen"),2-COUNTBLANK($G17:$H17),0) -> 1
A18: =OFFSET(A18,-1,0)+1 -> 8 | B18: =CONCATENATE(L18,IF(AND(M18<>L18,M18<>"")," ("&M18&")","")) -> National (nicht regional spezifiziert) | C18: =IF(AND(ISNUMBER(O18),O18>0),O18,"")&" ... "&IF(AND(ISNUMBER(P18),P18<9999),P18,"") -> 1984 ... 1994 | D18: =CONCATENATE(R18,IF(AND(S18<>R18,S18<>"")," ("&S18&")","")) -> Generic (Basis-Typ) | E18: =IF(W18<>"",$J18&"."&$K18&"."&E$9&"."&TEXT($N18,"00")&"."&$Q18,"") -> DE.N.SFH.08.Gen | F18: =IF(X18<>"",$J18&"."&$K18&"."&F$9&"."&TEXT($N18,"00")&"."&$Q18,"") -> DE.N.TH.08.Gen | G18: =IF(Y18<>"",$J18&"."&$K18&"."&G$9&"."&TEXT($N18,"00")&"."&$Q18,"") -> DE.N.MFH.08.Gen | H18: =IF(Z18<>"",$J18&"."&$K18&"."&H$9&"."&TEXT($N18,"00")&"."&$Q18,"") | J18: =OFFSET(J18,-1,0) -> DE | K18: N | L18: National | M18: nicht regional spezifiziert | N18: 8 | O18: 1984 | P18: 1994 | Q18: Gen | R18: Generic | S18: Basis-Typ | W18: ReEx.001 | X18: ReEx.001 | Y18: ReEx.001 | AB18: 1 | AC18: 1 | AD18: 1 | AE18: 1 | AG18: =IF(AND($K18="N",$Q18="Gen"),1,IF(OR($K18<>$K17,$Q18<>$Q17),MOD(AG17+1,2)+2,AG17)) -> 1 | AH18: =IF(AND($K18="N",$Q18="Gen"),1,IF(OR($K18<>$K17,$Q18<>$Q17),MOD(AH17+1,2)+2,AH17)) -> 1 | AI18: =IF(AND($K18="N",$Q18="Gen"),1,IF(OR($K18<>$K17,$Q18<>$Q17),MOD(AI17+1,2)+2,AI17)) -> 1 | AJ18: =IF(AND($K18="N",$Q18="Gen"),1,IF(OR($K18<>$K17,$Q18<>$Q17),MOD(AJ17+1,2)+2,AJ17)) -> 1 | AN18: =IF($K18<>"",2-COUNTBLANK($E18:$F18),0) -> 2 | AO18: =IF($K18<>"",2-COUNTBLANK($G18:$H18),0) -> 1 | AP18: =IF(AND($K18<>"",$Q18="Gen"),2-COUNTBLANK($E18:$F18),0) -> 2 | AQ18: =IF(AND($K18<>"",$Q18="Gen"),2-COUNTBLANK($G18:$H18),0) -> 1
A19: =OFFSET(A19,-1,0)+1 -> 9 | B19: =CONCATENATE(L19,IF(AND(M19<>L19,M19<>"")," ("&M19&")","")) -> National (nicht regional spezifiziert) | C19: =IF(AND(ISNUMBER(O19),O19>0),O19,"")&" ... "&IF(AND(ISNUMBER(P19),P19<9999),P19,"") -> 1995 ... 2001 | D19: =CONCATENATE(R19,IF(AND(S19<>R19,S19<>"")," ("&S19&")","")) -> Generic (Basis-Typ) | E19: =IF(W19<>"",$J19&"."&$K19&"."&E$9&"."&TEXT($N19,"00")&"."&$Q19,"") -> DE.N.SFH.09.Gen | F19: =IF(X19<>"",$J19&"."&$K19&"."&F$9&"."&TEXT($N19,"00")&"."&$Q19,"") -> DE.N.TH.09.Gen | G19: =IF(Y19<>"",$J19&"."&$K19&"."&G$9&"."&TEXT($N19,"00")&"."&$Q19,"") -> DE.N.MFH.09.Gen | H19: =IF(Z19<>"",$J19&"."&$K19&"."&H$9&"."&TEXT($N19,"00")&"."&$Q19,"") | J19: =OFFSET(J19,-1,0) -> DE | K19: N | L19: National | M19: nicht regional spezifiziert | N19: 9 | O19: 1995 | P19: 2001 | Q19: Gen | R19: Generic | S19: Basis-Typ | W19: ReEx.001 | X19: ReEx.001 | Y19: ReEx.001 | AB19: 1 | AC19: 1 | AD19: 1 | AE19: 1 | AG19: =IF(AND($K19="N",$Q19="Gen"),1,IF(OR($K19<>$K18,$Q19<>$Q18),MOD(AG18+1,2)+2,AG18)) -> 1 | AH19: =IF(AND($K19="N",$Q19="Gen"),1,IF(OR($K19<>$K18,$Q19<>$Q18),MOD(AH18+1,2)+2,AH18)) -> 1 | AI19: =IF(AND($K19="N",$Q19="Gen"),1,IF(OR($K19<>$K18,$Q19<>$Q18),MOD(AI18+1,2)+2,AI18)) -> 1 | AJ19: =IF(AND($K19="N",$Q19="Gen"),1,IF(OR($K19<>$K18,$Q19<>$Q18),MOD(AJ18+1,2)+2,AJ18)) -> 1 | AN19: =IF($K19<>"",2-COUNTBLANK($E19:$F19),0) -> 2 | AO19: =IF($K19<>"",2-COUNTBLANK($G19:$H19),0) -> 1 | AP19: =IF(AND($K19<>"",$Q19="Gen"),2-COUNTBLANK($E19:$F19),0) -> 2 | AQ19: =IF(AND($K19<>"",$Q19="Gen"),2-COUNTBLANK($G19:$H19),0) -> 1
A20: =OFFSET(A20,-1,0)+1 -> 10 | B20: =CONCATENATE(L20,IF(AND(M20<>L20,M20<>"")," ("&M20&")","")) -> National (nicht regional spezifiziert) | C20: =IF(AND(ISNUMBER(O20),O20>0),O20,"")&" ... "&IF(AND(ISNUMBER(P20),P20<9999),P20,"") -> 2002 ... 2009 | D20: =CONCATENATE(R20,IF(AND(S20<>R20,S20<>"")," ("&S20&")","")) -> Generic (Basis-Typ) | E20: =IF(W20<>"",$J20&"."&$K20&"."&E$9&"."&TEXT($N20,"00")&"."&$Q20,"") -> DE.N.SFH.10.Gen | F20: =IF(X20<>"",$J20&"."&$K20&"."&F$9&"."&TEXT($N20,"00")&"."&$Q20,"") -> DE.N.TH.10.Gen | G20: =IF(Y20<>"",$J20&"."&$K20&"."&G$9&"."&TEXT($N20,"00")&"."&$Q20,"") -> DE.N.MFH.10.Gen | H20: =IF(Z20<>"",$J20&"."&$K20&"."&H$9&"."&TEXT($N20,"00")&"."&$Q20,"") | J20: =OFFSET(J20,-1,0) -> DE | K20: N | L20: National | M20: nicht regional spezifiziert | N20: 10 | O20: 2002 | P20: 2009 | Q20: Gen | R20: Generic | S20: Basis-Typ | W20: ReEx.001 | X20: ReEx.001 | Y20: ReEx.001 | AB20: 1 | AC20: 1 | AD20: 1 | AE20: 1 | AG20: =IF(AND($K20="N",$Q20="Gen"),1,IF(OR($K20<>$K19,$Q20<>$Q19),MOD(AG19+1,2)+2,AG19)) -> 1 | AH20: =IF(AND($K20="N",$Q20="Gen"),1,IF(OR($K20<>$K19,$Q20<>$Q19),MOD(AH19+1,2)+2,AH19)) -> 1 | AI20: =IF(AND($K20="N",$Q20="Gen"),1,IF(OR($K20<>$K19,$Q20<>$Q19),MOD(AI19+1,2)+2,AI19)) -> 1 | AJ20: =IF(AND($K20="N",$Q20="Gen"),1,IF(OR($K20<>$K19,$Q20<>$Q19),MOD(AJ19+1,2)+2,AJ19)) -> 1 | AN20: =IF($K20<>"",2-COUNTBLANK($E20:$F20),0) -> 2 | AO20: =IF($K20<>"",2-COUNTBLANK($G20:$H20),0) -> 1 | AP20: =IF(AND($K20<>"",$Q20="Gen"),2-COUNTBLANK($E20:$F20),0) -> 2 | AQ20: =IF(AND($K20<>"",$Q20="Gen"),2-COUNTBLANK($G20:$H20),0) -> 1
A21: =OFFSET(A21,-1,0)+1 -> 11 | B21: =CONCATENATE(L21,IF(AND(M21<>L21,M21<>"")," ("&M21&")","")) -> National (nicht regional spezifiziert) | C21: =IF(AND(ISNUMBER(O21),O21>0),O21,"")&" ... "&IF(AND(ISNUMBER(P21),P21<9999),P21,"") -> 2010 ... 2015 | D21: =CONCATENATE(R21,IF(AND(S21<>R21,S21<>"")," ("&S21&")","")) -> Generic (Basis-Typ) | E21: =IF(W21<>"",$J21&"."&$K21&"."&E$9&"."&TEXT($N21,"00")&"."&$Q21,"") -> DE.N.SFH.11.Gen | F21: =IF(X21<>"",$J21&"."&$K21&"."&F$9&"."&TEXT($N21,"00")&"."&$Q21,"") -> DE.N.TH.11.Gen | G21: =IF(Y21<>"",$J21&"."&$K21&"."&G$9&"."&TEXT($N21,"00")&"."&$Q21,"") -> DE.N.MFH.11.Gen | H21: =IF(Z21<>"",$J21&"."&$K21&"."&H$9&"."&TEXT($N21,"00")&"."&$Q21,"") | J21: =OFFSET(J21,-1,0) -> DE | K21: N | L21: National | M21: nicht regional spezifiziert | N21: 11 | O21: 2010 | P21: 2015 | Q21: Gen | R21: Generic | S21: Basis-Typ | W21: ReEx.001 | X21: ReEx.001 | Y21: ReEx.001 | AB21: 1 | AC21: 1 | AD21: 1 | AE21: 1 | AG21: =IF(AND($K21="N",$Q21="Gen"),1,IF(OR($K21<>$K20,$Q21<>$Q20),MOD(AG20+1,2)+2,AG20)) -> 1 | AH21: =IF(AND($K21="N",$Q21="Gen"),1,IF(OR($K21<>$K20,$Q21<>$Q20),MOD(AH20+1,2)+2,AH20)) -> 1 | AI21: =IF(AND($K21="N",$Q21="Gen"),1,IF(OR($K21<>$K20,$Q21<>$Q20),MOD(AI20+1,2)+2,AI20)) -> 1 | AJ21: =IF(AND($K21="N",$Q21="Gen"),1,IF(OR($K21<>$K20,$Q21<>$Q20),MOD(AJ20+1,2)+2,AJ20)) -> 1 | AN21: =IF($K21<>"",2-COUNTBLANK($E21:$F21),0) -> 2 | AO21: =IF($K21<>"",2-COUNTBLANK($G21:$H21),0) -> 1 | AP21: =IF(AND($K21<>"",$Q21="Gen"),2-COUNTBLANK($E21:$F21),0) -> 2 | AQ21: =IF(AND($K21<>"",$Q21="Gen"),2-COUNTBLANK($G21:$H21),0) -> 1
A22: =OFFSET(A22,-1,0)+1 -> 12 | B22: =CONCATENATE(L22,IF(AND(M22<>L22,M22<>"")," ("&M22&")","")) -> National (nicht regional spezifiziert) | C22: =IF(AND(ISNUMBER(O22),O22>0),O22,"")&" ... "&IF(AND(ISNUMBER(P22),P22<9999),P22,"") -> 2016 ... | D22: =CONCATENATE(R22,IF(AND(S22<>R22,S22<>"")," ("&S22&")","")) -> Generic (Basis-Typ) | E22: =IF(W22<>"",$J22&"."&$K22&"."&E$9&"."&TEXT($N22,"00")&"."&$Q22,"") -> DE.N.SFH.12.Gen | F22: =IF(X22<>"",$J22&"."&$K22&"."&F$9&"."&TEXT($N22,"00")&"."&$Q22,"") -> DE.N.TH.12.Gen | G22: =IF(Y22<>"",$J22&"."&$K22&"."&G$9&"."&TEXT($N22,"00")&"."&$Q22,"") -> DE.N.MFH.12.Gen | H22: =IF(Z22<>"",$J22&"."&$K22&"."&H$9&"."&TEXT($N22,"00")&"."&$Q22,"") | J22: =OFFSET(J22,-1,0) -> DE | K22: N | L22: National | M22: nicht regional spezifiziert | N22: 12 | O22: 2016 | P22: 9999 | Q22: Gen | R22: Generic | S22: Basis-Typ | W22: ReEx.001 | X22: ReEx.001 | Y22: ReEx.001 | AB22: 1 | AC22: 1 | AD22: 1 | AE22: 1 | AG22: =IF(AND($K22="N",$Q22="Gen"),1,IF(OR($K22<>$K20,$Q22<>$Q20),MOD(AG20+1,2)+2,AG20)) -> 1 | AH22: =IF(AND($K22="N",$Q22="Gen"),1,IF(OR($K22<>$K20,$Q22<>$Q20),MOD(AH20+1,2)+2,AH20)) -> 1 | AI22: =IF(AND($K22="N",$Q22="Gen"),1,IF(OR($K22<>$K20,$Q22<>$Q20),MOD(AI20+1,2)+2,AI20)) -> 1 | AJ22: =IF(AND($K22="N",$Q22="Gen"),1,IF(OR($K22<>$K20,$Q22<>$Q20),MOD(AJ20+1,2)+2,AJ20)) -> 1 | AN22: =IF($K22<>"",2-COUNTBLANK($E22:$F22),0) -> 2 | AO22: =IF($K22<>"",2-COUNTBLANK($G22:$H22),0) -> 1 | AP22: =IF(AND($K22<>"",$Q22="Gen"),2-COUNTBLANK($E22:$F22),0) -> 2 | AQ22: =IF(AND($K22<>"",$Q22="Gen"),2-COUNTBLANK($G22:$H22),0) -> 1
A23: =OFFSET(A23,-1,0)+1 -> 13 | B23: =CONCATENATE(L23,IF(AND(M23<>L23,M23<>"")," ("&M23&")","")) -> National (nicht regional spezifiziert) | C23: =IF(AND(ISNUMBER(O23),O23>0),O23,"")&" ... "&IF(AND(ISNUMBER(P23),P23<9999),P23,"") -> 1969 ... 1978 | D23: =CONCATENATE(R23,IF(AND(S23<>R23,S23<>"")," ("&S23&")","")) -> Light Frame Structure (Fertighaus / Leichtbau) | E23: =IF(W23<>"",$J23&"."&$K23&"."&E$9&"."&TEXT($N23,"00")&"."&$Q23,"") -> DE.N.SFH.06.LightFrame | F23: =IF(X23<>"",$J23&"."&$K23&"."&F$9&"."&TEXT($N23,"00")&"."&$Q23,"") | G23: =IF(Y23<>"",$J23&"."&$K23&"."&G$9&"."&TEXT($N23,"00")&"."&$Q23,"") | H23: =IF(Z23<>"",$J23&"."&$K23&"."&H$9&"."&TEXT($N23,"00")&"."&$Q23,"") | J23: =OFFSET(J23,-1,0) -> DE | K23: N | L23: National | M23: nicht regional spezifiziert | N23: 6 | O23: 1969 | P23: 1978 | Q23: LightFrame | R23: Light Frame Structure | S23: Fertighaus / Leichtbau | T23: light frame structure: prefabricated building, constructed by use of wooden frames, insulation, and plasterboards / wooden boards | W23: ReEx.001 | AB23: 1 | AC23: 1 | AD23: 1 | AE23: 1 | AG23: =IF(AND($K23="N",$Q23="Gen"),1,IF(OR($K23<>$K22,$Q23<>$Q22),MOD(AG22+1,2)+2,AG22)) -> 2 | AH23: =IF(AND($K23="N",$Q23="Gen"),1,IF(OR($K23<>$K22,$Q23<>$Q22),MOD(AH22+1,2)+2,AH22)) -> 2 | AI23: =IF(AND($K23="N",$Q23="Gen"),1,IF(OR($K23<>$K22,$Q23<>$Q22),MOD(AI22+1,2)+2,AI22)) -> 2 | AJ23: =IF(AND($K23="N",$Q23="Gen"),1,IF(OR($K23<>$K22,$Q23<>$Q22),MOD(AJ22+1,2)+2,AJ22)) -> 2 | AN23: =IF($K23<>"",2-COUNTBLANK($E23:$F23),0) -> 1 | AO23: =IF($K23<>"",2-COUNTBLANK($G23:$H23),0) -> 0 | AP23: =IF(AND($K23<>"",$Q23="Gen"),2-COUNTBLANK($E23:$F23),0) -> 0 | AQ23: =IF(AND($K23<>"",$Q23="Gen"),2-COUNTBLANK($G23:$H23),0) -> 0
A24: =OFFSET(A24,-1,0)+1 -> 14 | B24: =CONCATENATE(L24,IF(AND(M24<>L24,M24<>"")," ("&M24&")","")) -> National (nicht regional spezifiziert) | C24: =IF(AND(ISNUMBER(O24),O24>0),O24,"")&" ... "&IF(AND(ISNUMBER(P24),P24<9999),P24,"") -> 1958 ... 1968 | D24: =CONCATENATE(R24,IF(AND(S24<>R24,S24<>"")," ("&S24&")","")) -> High-Rise Building (Hochhaus) | E24: =IF(W24<>"",$J24&"."&$K24&"."&E$9&"."&TEXT($N24,"00")&"."&$Q24,"") | F24: =IF(X24<>"",$J24&"."&$K24&"."&F$9&"."&TEXT($N24,"00")&"."&$Q24,"") | G24: =IF(Y24<>"",$J24&"."&$K24&"."&G$9&"."&TEXT($N24,"00")&"."&$Q24,"") | H24: =IF(Z24<>"",$J24&"."&$K24&"."&H$9&"."&TEXT($N24,"00")&"."&$Q24,"") -> DE.N.AB.05.HR | J24: =OFFSET(J24,-1,0) -> DE | K24: N | L24: National | M24: nicht regional spezifiziert | N24: 5 | O24: 1958 | P24: 1968 | Q24: HR | R24: High-Rise Building | S24: Hochhaus | T24: Western Germany | Z24: ReEx.001 | AB24: 1 | AC24: 1 | AD24: 1 | AE24: 1 | AG24: =IF(AND($K24="N",$Q24="Gen"),1,IF(OR($K24<>$K23,$Q24<>$Q23),MOD(AG23+1,2)+2,AG23)) -> 3 | AH24: =IF(AND($K24="N",$Q24="Gen"),1,IF(OR($K24<>$K23,$Q24<>$Q23),MOD(AH23+1,2)+2,AH23)) -> 3 | AI24: =IF(AND($K24="N",$Q24="Gen"),1,IF(OR($K24<>$K23,$Q24<>$Q23),MOD(AI23+1,2)+2,AI23)) -> 3 | AJ24: =IF(AND($K24="N",$Q24="Gen"),1,IF(OR($K24<>$K23,$Q24<>$Q23),MOD(AJ23+1,2)+2,AJ23)) -> 3 | AN24: =IF($K24<>"",2-COUNTBLANK($E24:$F24),0) -> 0 | AO24: =IF($K24<>"",2-COUNTBLANK($G24:$H24),0) -> 1 | AP24: =IF(AND($K24<>"",$Q24="Gen"),2-COUNTBLANK($E24:$F24),0) -> 0 | AQ24: =IF(AND($K24<>"",$Q24="Gen"),2-COUNTBLANK($G24:$H24),0) -> 0
A25: =OFFSET(A25,-1,0)+1 -> 15 | B25: =CONCATENATE(L25,IF(AND(M25<>L25,M25<>"")," ("&M25&")","")) -> National (nicht regional spezifiziert) | C25: =IF(AND(ISNUMBER(O25),O25>0),O25,"")&" ... "&IF(AND(ISNUMBER(P25),P25<9999),P25,"") -> 1969 ... 1978 | D25: =CONCATENATE(R25,IF(AND(S25<>R25,S25<>"")," ("&S25&")","")) -> High-Rise Building (Hochhaus) | E25: =IF(W25<>"",$J25&"."&$K25&"."&E$9&"."&TEXT($N25,"00")&"."&$Q25,"") | F25: =IF(X25<>"",$J25&"."&$K25&"."&F$9&"."&TEXT($N25,"00")&"."&$Q25,"") | G25: =IF(Y25<>"",$J25&"."&$K25&"."&G$9&"."&TEXT($N25,"00")&"."&$Q25,"") | H25: =IF(Z25<>"",$J25&"."&$K25&"."&H$9&"."&TEXT($N25,"00")&"."&$Q25,"") -> DE.N.AB.06.HR | J25: =OFFSET(J25,-1,0) -> DE | K25: N | L25: National | M25: nicht regional spezifiziert | N25: 6 | O25: 1969 | P25: 1978 | Q25: HR | R25: High-Rise Building | S25: Hochhaus | T25: Western Germany | Z25: ReEx.001 | AB25: 1 | AC25: 1 | AD25: 1 | AE25: 1 | AG25: =IF(AND($K25="N",$Q25="Gen"),1,IF(OR($K25<>$K24,$Q25<>$Q24),MOD(AG24+1,2)+2,AG24)) -> 3 | AH25: =IF(AND($K25="N",$Q25="Gen"),1,IF(OR($K25<>$K24,$Q25<>$Q24),MOD(AH24+1,2)+2,AH24)) -> 3 | AI25: =IF(AND($K25="N",$Q25="Gen"),1,IF(OR($K25<>$K24,$Q25<>$Q24),MOD(AI24+1,2)+2,AI24)) -> 3 | AJ25: =IF(AND($K25="N",$Q25="Gen"),1,IF(OR($K25<>$K24,$Q25<>$Q24),MOD(AJ24+1,2)+2,AJ24)) -> 3 | AN25: =IF($K25<>"",2-COUNTBLANK($E25:$F25),0) -> 0 | AO25: =IF($K25<>"",2-COUNTBLANK($G25:$H25),0) -> 1 | AP25: =IF(AND($K25<>"",$Q25="Gen"),2-COUNTBLANK($E25:$F25),0) -> 0 | AQ25: =IF(AND($K25<>"",$Q25="Gen"),2-COUNTBLANK($G25:$H25),0) -> 0
A26: =OFFSET(A26,-1,0)+1 -> 16 | B26: =CONCATENATE(L26,IF(AND(M26<>L26,M26<>"")," ("&M26&")","")) -> Eastern Germany / former GDR (neue Bundesländer) | C26: =IF(AND(ISNUMBER(O26),O26>0),O26,"")&" ... "&IF(AND(ISNUMBER(P26),P26<9999),P26,"") -> 1949 ... 1957 | D26: =CONCATENATE(R26,IF(AND(S26<>R26,S26<>"")," ("&S26&")","")) -> Generic (Basis-Typ) | E26: =IF(W26<>"",$J26&"."&$K26&"."&E$9&"."&TEXT($N26,"00")&"."&$Q26,"") | F26: =IF(X26<>"",$J26&"."&$K26&"."&F$9&"."&TEXT($N26,"00")&"."&$Q26,"") | G26: =IF(Y26<>"",$J26&"."&$K26&"."&G$9&"."&TEXT($N26,"00")&"."&$Q26,"") -> DE.East.MFH.04.Gen | H26: =IF(Z26<>"",$J26&"."&$K26&"."&H$9&"."&TEXT($N26,"00")&"."&$Q26,"") | J26: =OFFSET(J26,-1,0) -> DE | K26: East | L26: Eastern Germany / former GDR | M26: neue Bundesländer | N26: 4 | O26: 1949 | P26: 1957 | Q26: Gen | R26: Generic | S26: Basis-Typ | T26: panel building (Plattenbau) | Y26: ReEx.001 | AB26: 1 | AC26: 1 | AD26: 1 | AE26: 1 | AG26: =IF(AND($K26="N",$Q26="Gen"),1,IF(OR($K26<>$K25,$Q26<>$Q25),MOD(AG25+1,2)+2,AG25)) -> 2 | AH26: =IF(AND($K26="N",$Q26="Gen"),1,IF(OR($K26<>$K25,$Q26<>$Q25),MOD(AH25+1,2)+2,AH25)) -> 2 | AI26: =IF(AND($K26="N",$Q26="Gen"),1,IF(OR($K26<>$K25,$Q26<>$Q25),MOD(AI25+1,2)+2,AI25)) -> 2 | AJ26: =IF(AND($K26="N",$Q26="Gen"),1,IF(OR($K26<>$K25,$Q26<>$Q25),MOD(AJ25+1,2)+2,AJ25)) -> 2 | AN26: =IF($K26<>"",2-COUNTBLANK($E26:$F26),0) -> 0 | AO26: =IF($K26<>"",2-COUNTBLANK($G26:$H26),0) -> 1 | AP26: =IF(AND($K26<>"",$Q26="Gen"),2-COUNTBLANK($E26:$F26),0) -> 0 | AQ26: =IF(AND($K26<>"",$Q26="Gen"),2-COUNTBLANK($G26:$H26),0) -> 1
A27: =OFFSET(A27,-1,0)+1 -> 17 | B27: =CONCATENATE(L27,IF(AND(M27<>L27,M27<>"")," ("&M27&")","")) -> Eastern Germany / former GDR (neue Bundesländer) | C27: =IF(AND(ISNUMBER(O27),O27>0),O27,"")&" ... "&IF(AND(ISNUMBER(P27),P27<9999),P27,"") -> 1958 ... 1968 | D27: =CONCATENATE(R27,IF(AND(S27<>R27,S27<>"")," ("&S27&")","")) -> Generic (Basis-Typ) | E27: =IF(W27<>"",$J27&"."&$K27&"."&E$9&"."&TEXT($N27,"00")&"."&$Q27,"") | F27: =IF(X27<>"",$J27&"."&$K27&"."&F$9&"."&TEXT($N27,"00")&"."&$Q27,"") | G27: =IF(Y27<>"",$J27&"."&$K27&"."&G$9&"."&TEXT($N27,"00")&"."&$Q27,"") -> DE.East.MFH.05.Gen | H27: =IF(Z27<>"",$J27&"."&$K27&"."&H$9&"."&TEXT($N27,"00")&"."&$Q27,"") | J27: =OFFSET(J27,-1,0) -> DE | K27: East | L27: Eastern Germany / former GDR | M27: neue Bundesländer | N27: 5 | O27: 1958 | P27: 1968 | Q27: Gen | R27: Generic | S27: Basis-Typ | T27: panel building (Plattenbau) | Y27: ReEx.001 | AB27: 1 | AC27: 1 | AD27: 1 | AE27: 1 | AG27: =IF(AND($K27="N",$Q27="Gen"),1,IF(OR($K27<>$K26,$Q27<>$Q26),MOD(AG26+1,2)+2,AG26)) -> 2 | AH27: =IF(AND($K27="N",$Q27="Gen"),1,IF(OR($K27<>$K26,$Q27<>$Q26),MOD(AH26+1,2)+2,AH26)) -> 2 | AI27: =IF(AND($K27="N",$Q27="Gen"),1,IF(OR($K27<>$K26,$Q27<>$Q26),MOD(AI26+1,2)+2,AI26)) -> 2 | AJ27: =IF(AND($K27="N",$Q27="Gen"),1,IF(OR($K27<>$K26,$Q27<>$Q26),MOD(AJ26+1,2)+2,AJ26)) -> 2 | AN27: =IF($K27<>"",2-COUNTBLANK($E27:$F27),0) -> 0 | AO27: =IF($K27<>"",2-COUNTBLANK($G27:$H27),0) -> 1 | AP27: =IF(AND($K27<>"",$Q27="Gen"),2-COUNTBLANK($E27:$F27),0) -> 0 | AQ27: =IF(AND($K27<>"",$Q27="Gen"),2-COUNTBLANK($G27:$H27),0) -> 1
A28: =OFFSET(A28,-1,0)+1 -> 18 | B28: =CONCATENATE(L28,IF(AND(M28<>L28,M28<>"")," ("&M28&")","")) -> Eastern Germany / former GDR (neue Bundesländer) | C28: =IF(AND(ISNUMBER(O28),O28>0),O28,"")&" ... "&IF(AND(ISNUMBER(P28),P28<9999),P28,"") -> 1969 ... 1978 | D28: =CONCATENATE(R28,IF(AND(S28<>R28,S28<>"")," ("&S28&")","")) -> Generic (Basis-Typ) | E28: =IF(W28<>"",$J28&"."&$K28&"."&E$9&"."&TEXT($N28,"00")&"."&$Q28,"") | F28: =IF(X28<>"",$J28&"."&$K28&"."&F$9&"."&TEXT($N28,"00")&"."&$Q28,"") | G28: =IF(Y28<>"",$J28&"."&$K28&"."&G$9&"."&TEXT($N28,"00")&"."&$Q28,"") | H28: =IF(Z28<>"",$J28&"."&$K28&"."&H$9&"."&TEXT($N28,"00")&"."&$Q28,"") -> DE.East.AB.06.Gen | J28: =OFFSET(J28,-1,0) -> DE | K28: East | L28: Eastern Germany / former GDR | M28: neue Bundesländer | N28: 6 | O28: 1969 | P28: 1978 | Q28: Gen | R28: Generic | S28: Basis-Typ | T28: panel building (Plattenbau) | Z28: ReEx.001 | AB28: 1 | AC28: 1 | AD28: 1 | AE28: 1 | AG28: =IF(AND($K28="N",$Q28="Gen"),1,IF(OR($K28<>$K27,$Q28<>$Q27),MOD(AG27+1,2)+2,AG27)) -> 2 | AH28: =IF(AND($K28="N",$Q28="Gen"),1,IF(OR($K28<>$K27,$Q28<>$Q27),MOD(AH27+1,2)+2,AH27)) -> 2 | AI28: =IF(AND($K28="N",$Q28="Gen"),1,IF(OR($K28<>$K27,$Q28<>$Q27),MOD(AI27+1,2)+2,AI27)) -> 2 | AJ28: =IF(AND($K28="N",$Q28="Gen"),1,IF(OR($K28<>$K27,$Q28<>$Q27),MOD(AJ27+1,2)+2,AJ27)) -> 2 | AN28: =IF($K28<>"",2-COUNTBLANK($E28:$F28),0) -> 0 | AO28: =IF($K28<>"",2-COUNTBLANK($G28:$H28),0) -> 1 | AP28: =IF(AND($K28<>"",$Q28="Gen"),2-COUNTBLANK($E28:$F28),0) -> 0 | AQ28: =IF(AND($K28<>"",$Q28="Gen"),2-COUNTBLANK($G28:$H28),0) -> 1
A29: =OFFSET(A29,-1,0)+1 -> 19 | B29: =CONCATENATE(L29,IF(AND(M29<>L29,M29<>"")," ("&M29&")","")) -> Eastern Germany / former GDR (neue Bundesländer) | C29: =IF(AND(ISNUMBER(O29),O29>0),O29,"")&" ... "&IF(AND(ISNUMBER(P29),P29<9999),P29,"") -> 1979 ... 1983 | D29: =CONCATENATE(R29,IF(AND(S29<>R29,S29<>"")," ("&S29&")","")) -> Generic (Basis-Typ) | E29: =IF(W29<>"",$J29&"."&$K29&"."&E$9&"."&TEXT($N29,"00")&"."&$Q29,"") | F29: =IF(X29<>"",$J29&"."&$K29&"."&F$9&"."&TEXT($N29,"00")&"."&$Q29,"") | G29: =IF(Y29<>"",$J29&"."&$K29&"."&G$9&"."&TEXT($N29,"00")&"."&$Q29,"") | H29: =IF(Z29<>"",$J29&"."&$K29&"."&H$9&"."&TEXT($N29,"00")&"."&$Q29,"") -> DE.East.AB.07.Gen | J29: =OFFSET(J29,-1,0) -> DE | K29: East | L29: Eastern Germany / former GDR | M29: neue Bundesländer | N29: 7 | O29: 1979 | P29: 1983 | Q29: Gen | R29: Generic | S29: Basis-Typ | T29: panel building (Plattenbau) | Z29: ReEx.001 | AB29: 1 | AC29: 1 | AD29: 1 | AE29: 1 | AG29: =IF(AND($K29="N",$Q29="Gen"),1,IF(OR($K29<>$K28,$Q29<>$Q28),MOD(AG28+1,2)+2,AG28)) -> 2 | AH29: =IF(AND($K29="N",$Q29="Gen"),1,IF(OR($K29<>$K28,$Q29<>$Q28),MOD(AH28+1,2)+2,AH28)) -> 2 | AI29: =IF(AND($K29="N",$Q29="Gen"),1,IF(OR($K29<>$K28,$Q29<>$Q28),MOD(AI28+1,2)+2,AI28)) -> 2 | AJ29: =IF(AND($K29="N",$Q29="Gen"),1,IF(OR($K29<>$K28,$Q29<>$Q28),MOD(AJ28+1,2)+2,AJ28)) -> 2 | AN29: =IF($K29<>"",2-COUNTBLANK($E29:$F29),0) -> 0 | AO29: =IF($K29<>"",2-COUNTBLANK($G29:$H29),0) -> 1 | AP29: =IF(AND($K29<>"",$Q29="Gen"),2-COUNTBLANK($E29:$F29),0) -> 0 | AQ29: =IF(AND($K29<>"",$Q29="Gen"),2-COUNTBLANK($G29:$H29),0) -> 1
A30: =OFFSET(A30,-1,0)+1 -> 20 | B30: =CONCATENATE(L30,IF(AND(M30<>L30,M30<>"")," ("&M30&")","")) -> Eastern Germany / former GDR (neue Bundesländer) | C30: =IF(AND(ISNUMBER(O30),O30>0),O30,"")&" ... "&IF(AND(ISNUMBER(P30),P30<9999),P30,"") -> 1984 ... 1994 | D30: =CONCATENATE(R30,IF(AND(S30<>R30,S30<>"")," ("&S30&")","")) -> Generic (Basis-Typ) | E30: =IF(W30<>"",$J30&"."&$K30&"."&E$9&"."&TEXT($N30,"00")&"."&$Q30,"") | F30: =IF(X30<>"",$J30&"."&$K30&"."&F$9&"."&TEXT($N30,"00")&"."&$Q30,"") | G30: =IF(Y30<>"",$J30&"."&$K30&"."&G$9&"."&TEXT($N30,"00")&"."&$Q30,"") | H30: =IF(Z30<>"",$J30&"."&$K30&"."&H$9&"."&TEXT($N30,"00")&"."&$Q30,"") -> DE.East.AB.08.Gen | J30: =OFFSET(J30,-1,0) -> DE | K30: East | L30: Eastern Germany / former GDR | M30: neue Bundesländer | N30: 8 | O30: 1984 | P30: 1994 | Q30: Gen | R30: Generic | S30: Basis-Typ | T30: panel building (Plattenbau) | Z30: ReEx.001 | AB30: 1 | AC30: 1 | AD30: 1 | AE30: 1 | AG30: =IF(AND($K30="N",$Q30="Gen"),1,IF(OR($K30<>$K29,$Q30<>$Q29),MOD(AG29+1,2)+2,AG29)) -> 2 | AH30: =IF(AND($K30="N",$Q30="Gen"),1,IF(OR($K30<>$K29,$Q30<>$Q29),MOD(AH29+1,2)+2,AH29)) -> 2 | AI30: =IF(AND($K30="N",$Q30="Gen"),1,IF(OR($K30<>$K29,$Q30<>$Q29),MOD(AI29+1,2)+2,AI29)) -> 2 | AJ30: =IF(AND($K30="N",$Q30="Gen"),1,IF(OR($K30<>$K29,$Q30<>$Q29),MOD(AJ29+1,2)+2,AJ29)) -> 2 | AN30: =IF($K30<>"",2-COUNTBLANK($E30:$F30),0) -> 0 | AO30: =IF($K30<>"",2-COUNTBLANK($G30:$H30),0) -> 1 | AP30: =IF(AND($K30<>"",$Q30="Gen"),2-COUNTBLANK($E30:$F30),0) -> 0 | AQ30: =IF(AND($K30<>"",$Q30="Gen"),2-COUNTBLANK($G30:$H30),0) -> 1
A31: =OFFSET(A31,-1,0)+1 -> 21 | B31: =CONCATENATE(L31,IF(AND(M31<>L31,M31<>"")," ("&M31&")","")) -> Eastern Germany / former GDR (neue Bundesländer) | C31: =IF(AND(ISNUMBER(O31),O31>0),O31,"")&" ... "&IF(AND(ISNUMBER(P31),P31<9999),P31,"") -> 1969 ... 1978 | D31: =CONCATENATE(R31,IF(AND(S31<>R31,S31<>"")," ("&S31&")","")) -> High-Rise Building (Hochhaus) | E31: =IF(W31<>"",$J31&"."&$K31&"."&E$9&"."&TEXT($N31,"00")&"."&$Q31,"") | F31: =IF(X31<>"",$J31&"."&$K31&"."&F$9&"."&TEXT($N31,"00")&"."&$Q31,"") | G31: =IF(Y31<>"",$J31&"."&$K31&"."&G$9&"."&TEXT($N31,"00")&"."&$Q31,"") | H31: =IF(Z31<>"",$J31&"."&$K31&"."&H$9&"."&TEXT($N31,"00")&"."&$Q31,"") -> DE.East.AB.06.HR | J31: =OFFSET(J31,-1,0) -> DE | K31: East | L31: Eastern Germany / former GDR | M31: neue Bundesländer | N31: 6 | O31: 1969 | P31: 1978 | Q31: HR | R31: High-Rise Building | S31: Hochhaus | T31: panel building (Plattenbau) | Z31: ReEx.001 | AB31: 1 | AC31: 1 | AD31: 1 | AE31: 1 | AG31: =IF(AND($K31="N",$Q31="Gen"),1,IF(OR($K31<>$K30,$Q31<>$Q30),MOD(AG30+1,2)+2,AG30)) -> 3 | AH31: =IF(AND($K31="N",$Q31="Gen"),1,IF(OR($K31<>$K30,$Q31<>$Q30),MOD(AH30+1,2)+2,AH30)) -> 3 | AI31: =IF(AND($K31="N",$Q31="Gen"),1,IF(OR($K31<>$K30,$Q31<>$Q30),MOD(AI30+1,2)+2,AI30)) -> 3 | AJ31: =IF(AND($K31="N",$Q31="Gen"),1,IF(OR($K31<>$K30,$Q31<>$Q30),MOD(AJ30+1,2)+2,AJ30)) -> 3 | AN31: =IF($K31<>"",2-COUNTBLANK($E31:$F31),0) -> 0 | AO31: =IF($K31<>"",2-COUNTBLANK($G31:$H31),0) -> 1 | AP31: =IF(AND($K31<>"",$Q31="Gen"),2-COUNTBLANK($E31:$F31),0) -> 0 | AQ31: =IF(AND($K31<>"",$Q31="Gen"),2-COUNTBLANK($G31:$H31),0) -> 0
A32: =OFFSET(A32,-1,0)+1 -> 22 | B32: =CONCATENATE(L32,IF(AND(M32<>L32,M32<>"")," ("&M32&")","")) -> Eastern Germany / former GDR (neue Bundesländer) | C32: =IF(AND(ISNUMBER(O32),O32>0),O32,"")&" ... "&IF(AND(ISNUMBER(P32),P32<9999),P32,"") -> 1979 ... 1983 | D32: =CONCATENATE(R32,IF(AND(S32<>R32,S32<>"")," ("&S32&")","")) -> High-Rise Building (Hochhaus) | E32: =IF(W32<>"",$J32&"."&$K32&"."&E$9&"."&TEXT($N32,"00")&"."&$Q32,"") | F32: =IF(X32<>"",$J32&"."&$K32&"."&F$9&"."&TEXT($N32,"00")&"."&$Q32,"") | G32: =IF(Y32<>"",$J32&"."&$K32&"."&G$9&"."&TEXT($N32,"00")&"."&$Q32,"") | H32: =IF(Z32<>"",$J32&"."&$K32&"."&H$9&"."&TEXT($N32,"00")&"."&$Q32,"") -> DE.East.AB.07.HR | J32: =OFFSET(J32,-1,0) -> DE | K32: East | L32: Eastern Germany / former GDR | M32: neue Bundesländer | N32: 7 | O32: 1979 | P32: 1983 | Q32: HR | R32: High-Rise Building | S32: Hochhaus | T32: panel building (Plattenbau) | Z32: ReEx.001 | AB32: 1 | AC32: 1 | AD32: 1 | AE32: 1 | AG32: =IF(AND($K32="N",$Q32="Gen"),1,IF(OR($K32<>$K31,$Q32<>$Q31),MOD(AG31+1,2)+2,AG31)) -> 3 | AH32: =IF(AND($K32="N",$Q32="Gen"),1,IF(OR($K32<>$K31,$Q32<>$Q31),MOD(AH31+1,2)+2,AH31)) -> 3 | AI32: =IF(AND($K32="N",$Q32="Gen"),1,IF(OR($K32<>$K31,$Q32<>$Q31),MOD(AI31+1,2)+2,AI31)) -> 3 | AJ32: =IF(AND($K32="N",$Q32="Gen"),1,IF(OR($K32<>$K31,$Q32<>$Q31),MOD(AJ31+1,2)+2,AJ31)) -> 3 | AN32: =IF($K32<>"",2-COUNTBLANK($E32:$F32),0) -> 0 | AO32: =IF($K32<>"",2-COUNTBLANK($G32:$H32),0) -> 1 | AP32: =IF(AND($K32<>"",$Q32="Gen"),2-COUNTBLANK($E32:$F32),0) -> 0 | AQ32: =IF(AND($K32<>"",$Q32="Gen"),2-COUNTBLANK($G32:$H32),0) -> 0
A33: =OFFSET(A33,-1,0)+1 -> 23 | B33: =CONCATENATE(L33,IF(AND(M33<>L33,M33<>"")," ("&M33&")","")) | C33: =IF(AND(ISNUMBER(O33),O33>0),O33,"")&" ... "&IF(AND(ISNUMBER(P33),P33<9999),P33,"") -> ... | D33: =CONCATENATE(R33,IF(AND(S33<>R33,S33<>"")," ("&S33&")","")) | E33: =IF(W33<>"",$J33&"."&$K33&"."&E$9&"."&TEXT($N33,"00")&"."&$Q33,"") | F33: =IF(X33<>"",$J33&"."&$K33&"."&F$9&"."&TEXT($N33,"00")&"."&$Q33,"") | G33: =IF(Y33<>"",$J33&"."&$K33&"."&G$9&"."&TEXT($N33,"00")&"."&$Q33,"") | H33: =IF(Z33<>"",$J33&"."&$K33&"."&H$9&"."&TEXT($N33,"00")&"."&$Q33,"") | J33: =OFFSET(J33,-1,0) -> DE | Q33: Gen | AB33: 1 | AC33: 1 | AD33: 1 | AE33: 1 | AG33: =IF(AND($K33="N",$Q33="Gen"),1,IF(OR($K33<>$K32,$Q33<>$Q32),MOD(AG32+1,2)+2,AG32)) -> 2 | AH33: =IF(AND($K33="N",$Q33="Gen"),1,IF(OR($K33<>$K32,$Q33<>$Q32),MOD(AH32+1,2)+2,AH32)) -> 2 | AI33: =IF(AND($K33="N",$Q33="Gen"),1,IF(OR($K33<>$K32,$Q33<>$Q32),MOD(AI32+1,2)+2,AI32)) -> 2 | AJ33: =IF(AND($K33="N",$Q33="Gen"),1,IF(OR($K33<>$K32,$Q33<>$Q32),MOD(AJ32+1,2)+2,AJ32)) -> 2 | AN33: =IF($K33<>"",2-COUNTBLANK($E33:$F33),0) -> 0 | AO33: =IF($K33<>"",2-COUNTBLANK($G33:$H33),0) -> 0 | AP33: =IF(AND($K33<>"",$Q33="Gen"),2-COUNTBLANK($E33:$F33),0) -> 0 | AQ33: =IF(AND($K33<>"",$Q33="Gen"),2-COUNTBLANK($G33:$H33),0) -> 0
